Workbook

Sheet LIASSES MULTI APPARTEMENT
A1: LIASSES FISCALES MULTI APPARTEMENTS
A4: Année Fiscale | B4: =YEAR(TODAY())-1 -> 2025 | D4: Espace Pro : impot gouv : Déclarer : Résultat
A6: Compte de resultat
A8: Année | B8: =B4 -> 2025 | D8: Année | E8: =B4+1 -> 2026
A9: Dotation aux ammortissements (année en cours) | B9: ='Appartement 1'!B83+'Appartement 2'!B83 -> 8325 | D9: Dotation aux ammortissements (année en cours) | E9: ='Appartement 1'!E83+'Appartement 2'!E83 -> 8325
A10: Loyer | B10: ='Appartement 1'!B84+'Appartement 2'!B84 -> 16000 | D10: Loyer | E10: ='Appartement 1'!E84+'Appartement 2'!E84 -> 16000
A11: Charges | B11: ='Appartement 1'!B85+'Appartement 2'!B85 -> 20400 | D11: Charges | E11: ='Appartement 1'!E85+'Appartement 2'!E85 -> 2400
A12: Taxes | B12: ='Appartement 1'!B86+'Appartement 2'!B86 -> 0 | D12: Taxes | E12: ='Appartement 1'!E86+'Appartement 2'!E86 -> 0
A13: Interets d'emprunts | B13: ='Appartement 1'!B87+'Appartement 2'!B87 -> 6000 | D13: Interets d'emprunts | E13: ='Appartement 1'!E87+'Appartement 2'!E87 -> 6000
A14: Resultat comptable avant dotation aux amortissements | B14: =B10-B11-B12-B13 -> -10400 | D14: Resultat comptable avant dotation aux amortissements | E14: =E10-E11-E12-E13 -> 7600
A15: Déficits reportables (Nouvellement crée) | B15: =IF(B14<0,-B14,0) -> 10400 | D15: Déficits reportables (Nouvellement crée) | E15: =IF(E14<0,-E14,0) -> 0
A16: Resultat comptable après dotation aux amortissements | B16: =B14-B9 -> -18725 | D16: Resultat comptable après dotation aux amortissements | E16: =E14-E9 -> -725
A17: Amortissement excédentaires (Nouvellement crée) | B17: =MIN(B9 , MAX(0 , B9 - B14)) -> 8325 | C17: =max(0-B16-B15) -> 8325 | D17: Amortissement excédentaires | E17: =MIN(E9 , MAX(0 , E9 - E14)) -> 725
A18: Résultat après imputation des amortissements excédentaires | B18: =B17+B16 -> -10400 | D18: Résultat après imputation des amortissements excédentaires | E18: =E17+E16 -> 0
A19: Amortissement excédentaires ANTERIEURS | B19: ='Appartement 1'!B93+'Appartement 2'!B933 -> 0 | D19: Amortissement excédentaires ANTERIEURS | E19: =B22 -> 8325
A20: Amortissement ANTERIEURS imputés | B20: =IF(B16<=0,0,MIN(B16,B19)) -> 0 | D20: Amortissement ANTERIEURS imputés | E20: =IF(E16<=0,0,MIN(E16,E19)) -> 0
A21: Amortissement ANTERIEURS restants | B21: =B19-B20 -> 0 | D21: Amortissement ANTERIEURS restants | E21: =E19-E20 -> 8325
A22: Amortissements restants à reporter pour les années ultérieures | B22: =B21+B17 -> 8325 | D22: Amortissements restants à reporter pour les années ultérieures | E22: =E21+E17 -> 9050
A23: Résultat après imputation des amortisseùents excédentaires ANTERIEURS | B23: =B18-B20 -> -10400 | D23: Résultat après imputation des amortisseùents excédentaires ANTERIEURS | E23: =E18-E20 -> 0
A24: Déficits ANTERIEURS | B24: 0 | D24: Déficits ANTERIEURS | E24: =B27 -> 10400
A25: Déficits ANTERIEURS imputés | B25: =IF(B23<=0,0,MIN(B23,B24)) -> 0 | D25: Déficits ANTERIEURS imputés | E25: =IF(E23<=0,0,MIN(E23,E24)) -> 0
A26: Déficits ANTERIEURS restants | B26: =B24+B25 -> 0 | D26: Déficits ANTERIEURS restants | E26: =E24+E25 -> 10400
A27: Déficits restants à reportrer pour les années ultérieures | B27: =B26+B15 -> 10400 | D27: Déficits restants à reportrer pour les années ultérieures | E27: =E26+E15 -> 10400
A28: Resultat fiscal après imputation : 1/ amortissements excedentaires de l'année en cours 2/ amortissement excédentaires antérieurs 3/ déficits antérieurs | B28: =B23-B25 -> -10400 | D28: Resultat fiscal après imputation : 1/ amortissements excedentaires de l'année en cours 2/ amortissement excédentaires antérieurs 3/ déficits antérieurs | E28: =E23-E25 -> 0
A29: Disponibilité Antérieurs | B29: 0 | D29: Disponibilité Antérieurs | E29: =B30 -> 0
A30: Disponibilités | B30: =Max(0,B10-B11-B12-B13)+B29 -> 0 | D30: Disponibilités | E30: =Max(0,E10-E11-E12-E13)+E29 -> 7600
A33: BILAN (2033-A)
A34: Année | B34: =B4 -> 2025 | I34: Année | J34: =B4+1 -> 2026
B35: ACTIF | C35: BRUT | E35: Amortissement/provisions | G35: Net Exercice N | J35: ACTIF | K35: BRUT | M35: Amortissement/provisions | O35: Net Exercice N
A36: Actif immobilisé | B36: Immobilisation corporelles | C36: "028" | D36: ='Appartement 1'!D110+'Appartement 2'!D108 -> 300000 | E36: "030" | F36: ='Appartement 1'!F110+'Appartement 2'!F108 -> 8325 | G36: =D36-F36 -> 291675 | I36: Actif immobilisé | J36: Immobilisation corporelles | K36: "028" | L36: =D36 -> 300000 | M36: "030" | N36: ='Appartement 1'!N110+'Appartement 2'!N108 -> 16650 | O36: =L36-N36 -> 283350
B37: Immobilisation financière | C37: "040" | D37: 0 | E37: "042" | F37: 0 | G37: 0 | J37: Immobilisation financière | K37: "040" | L37: 0 | M37: "042" | N37: 0 | O37: 0
B38: Total | C38: "044" | D38: =D36+D37 -> 300000 | E38: "048" | F38: =F36+F37 -> 8325 | G38: =G36+G37 -> 291675 | J38: Total | K38: "044" | L38: =L36+L37 -> 300000 | M38: "048" | N38: =N36+N37 -> 16650 | O38: =O36+O37 -> 283350
A39: Actif Circulant | I39: Actif Circulant
B40: Disponibilités | C40: "084" | D40: =B30 -> 0 | G40: =D40 -> 0 | J40: Disponibilités | K40: "084" | L40: =J30 | O40: =L40
A42: Total | C42: "110" | D42: =D38+D40 -> 300000 | E42: "112" | F42: =F38 -> 8325 | G42: =G38+G40 -> 291675 | I42: Total | K42: "110" | L42: =L38+L40 -> 300000 | M42: "112" | N42: =N38 -> 16650 | O42: =O38+O40 -> 283350
B43: PASSIF | G43: Net Exercice N | J43: PASSIF | O43: Net Exercice N
B44: Capital social ou individuel | C44: "120" | G44: =G42-G46-G48 -> 134400 | J44: Capital social ou individuel | K44: "120" | O44: =O42-O46-O48 -> 124575
B46: Resultat de l'exercice | C46: "136" | G46: =B16 -> -18725 | J46: Resultat de l'exercice | K46: "136" | O46: =E16 -> -725
B48: Emrpunt et dettes assimilés | C48: "156" | G48: ='Appartement 1'!G122 +'Appartement 2'!G120 -> 176000 | J48: Emrpunt et dettes assimilés | K48: "156" | O48: ='Appartement 1'!O122+'Appartement 2'!O120 -> 159500
B49: Total II | C49: "176" | G49: =G48 -> 176000 | J49: Total II | K49: "176" | O49: =O48 -> 159500
...

Sheet Appartement 1
A1: Etape 1 prix de départ Appartement 1: | D1: Espace Pro : impot gouv : Déclarer : Résultat
A4: Prix d'achat | B4: 150000
A5: Frais de notaire | B5: =0 -> 0
A6: frais d'agence | B6: =0 -> 0
A7: Mobilier | B7: =0 -> 0
A8: Travaux à amortir | B8: =0 -> 0
A9: Base amortissable | B9: =IF(B4>0,SUM(B4:B6),IF(E4>0,E4,0)) -> 150000
A11: Etape 2 : Décomposition et amortissement
A12: Date de début d'activité | B12: 45658
A13: Année de début d'activité | B13: =YEAR(B12) -> 2025 | E13: Année d'exercice | F13: =YEAR(TODAY())-1 -> 2025 | H13: =F13-B13+26 -> 26
A14: Prorata | B14: =YEARFRAC(B12,DATE(YEAR(B12)+1,1,1),4) -> 1 | AD14: Travaux/Mobilier | AE14: Montant | AF14: Date debut | AG14: Nbr année amortissement | AH14: Prorata première année
A15: Terrain | B15: =15% -> 0.15 | AD15: Travaux/Mobilier 1 | AE15: 0 | AF15: 45809 | AG15: 10 | AH15: =YEARFRAC(AF15,DATE(YEAR(AF15)+1,1,1),4) -> 0.58333333
A16: Structure (Gros oeuvre) | B16: =40% -> 0.4 | C16: du total sur | D16: 50 | E16: ans | AD16: Travaux/Mobilier 2 | AE16: 0 | AF16: 46174 | AG16: 10 | AH16: =YEARFRAC(AF16,DATE(YEAR(AF16)+1,1,1),4) -> 0.58333333
A17: Façade, étanchieté | B17: =15% -> 0.15 | C17: du total sur | D17: 40 | E17: ans | AD17: Travaux/Mobilier 3 | AE17: 0 | AF17: 46539 | AG17: 10 | AH17: =YEARFRAC(AF17,DATE(YEAR(AF17)+1,1,1),4) -> 0.58333333
A18: IGT, Equipement | B18: =15% -> 0.15 | C18: du total sur | D18: 25 | E18: ans | AD18: Travaux/Mobilier 4 | AE18: 0 | AF18: 46905 | AG18: 10 | AH18: =YEARFRAC(AF18,DATE(YEAR(AF18)+1,1,1),4) -> 0.58333333
A19: Agencements (cloisons, chapes, platerie, revetement, plomberie, cablage) | B19: =15% -> 0.15 | C19: du total sur | D19: 15 | E19: ans | AD19: Travaux/Mobilier 5 | AE19: 0 | AF19: 47270 | AG19: 10 | AH19: =YEARFRAC(AF19,DATE(YEAR(AF19)+1,1,1),4) -> 0.58333333
A20: Mobilier+travaux avant 1ere location | B20: =B7+B8 -> 0 | D20: 10 | E20: ans | AD20: Travaux/Mobilier 6 | AE20: 0 | AF20: 47635 | AG20: 10 | AH20: =YEARFRAC(AF20,DATE(YEAR(AF20)+1,1,1),4) -> 0.58333333
A21: Frais de notaire | B21: =B5 -> 0 | D21: 0 | AD21: Travaux/Mobilier 7 | AE21: 0 | AF21: 48000 | AG21: 10 | AH21: =YEARFRAC(AF21,DATE(YEAR(AF21)+1,1,1),4) -> 0.58333333
A22: Frais d'agence | B22: =B6 -> 0 | D22: 0 | AD22: Travaux/Mobilier 8 | AE22: 0 | AF22: 48000 | AG22: 10 | AH22: =YEARFRAC(AF22,DATE(YEAR(AF22)+1,1,1),4) -> 0.58333333
AD23: Travaux/Mobilier 9 | AE23: 0 | AF23: 48000 | AG23: 10 | AH23: =YEARFRAC(AF23,DATE(YEAR(AF23)+1,1,1),4) -> 0.58333333
C24: Augmentation Amortissement (dotations) | K24: Immobilisations net | Q24: Ammortissement début d'excercice | W24: Ammortissement fin exercice | AD24: Travaux/Mobilier 10 | AE24: 0 | AF24: 48000 | AG24: 10 | AH24: =YEARFRAC(AF24,DATE(YEAR(AF24)+1,1,1),4) -> 0.58333333
A25: Année | B25: Structure | C25: Façade | D25: Equipement | E25: Agencement | F25: Autres immobilisations corporelles | G25: Total Ammortissement | H25: Construction | I25: Construction | J25: Immo equipement | K25: Immo agencement | L25: Autres immobilisations corporelles | N25: Terrain | O25: Total | P25: Construction | Q25: Terrain | R25: Equipement | S25: Agencement | T25: Autres immobilisations corporelles | U25: Total | V25: Construction | W25: Terrain | X25: Equipement | Y25: Agencement | Z25: Autres immobilisations corporelles | AB25: Total
A26: 2025 | B26: =IF(A26<$B$13+$D$16,$B$16*$B$9/$D$16,0)*B14 -> 1200 | C26: =IF(A26<$B$13+$D17,$B$17*$B$9/$D$17,0)*B14 -> 562.5 | D26: =IF(A26<$B$13+$D18,$B$18*$B$9/$D$18,0)*B14 -> 900 | E26: =IF(A26<$B$13+$D$19,$B$19*$B$9/$D$19,0)*B14 -> 1500 | F26: =(IF(A26<$B$13+$D$20,$B$20/$D$20,0)*B14) -> 0 | G26: =SUM(B26:F26) -> 4162.5 | H26: =B26+C26 -> 1762.5 | I26: =$B$9*($B$16+$B$17)-V26 -> 80737.5 | J26: =$B$9*($B$18)-X26 -> 21600 | K26: =$B$9*($B$19)-Y26 -> 21000 | L26: =$B$20-Z26+AJ26 -> 0 | N26: =$B$9*$B$15 -> 22500 | O26: =SUM(I26:N26) -> 145837.5 | P26: 0 | Q26: 0 | R26: 0 | S26: 0 | T26: 0 | U26: 0 | V26: =P26+H26 -> 1762.5 | W26: 0 | X26: =R26+D26 -> 900 | Y26: =S26+E26 -> 1500 | Z26: =T26+F26 -> 0 | AB26: =SUM(V26:AA26) -> 4162.5
A27: 2026 | B27: =IF(A27=$B$13+$D$16,($B$16*$B$9/$D$16)*(1-$B$14),IF(A27<$B$13+$D$16,$B$16*$B$9/$D$16,0)) -> 1200 | C27: =IF(A27=$B$13+$D$17,($B$17*$B$9/$D$17)*(1-$B$14),IF(A27<$B$13+$D$17,$B$17*$B$9/$D$17,0)) -> 562.5 | D27: =IF(A27=$B$13+$D$18,($B$18*$B$9/$D$18)*(1-$B$14),IF(A27<$B$13+$D$18,$B$18*$B$9/$D$18,0)) -> 900 | E27: =IF(A27=$B$13+$D$19,($B$19*$B$9/$D$19)*(1-$B$14),IF(A27<$B$13+$D$19,$B$19*$B$9/$D$19,0)) -> 1500 | F27: =IF(A27=$B$13+$D$20,($B$20/$D$20)*(1-$B$14),IF(A27<$B$13+$D$20,$B$20/$D$20,0)) -> 0 | G27: =SUM(B27:F27) -> 4162.5 | H27: =B27+C27 -> 1762.5 | I27: =$B$9*($B$16+$B$17)-V27 -> 78975 | J27: =$B$9*($B$18)-X27 -> 20700 | K27: =$B$9*($B$19)-Y27 -> 19500 | L27: =$B$20-Z27+AJ27 -> 0 | N27: =$B$9*$B$15 -> 22500 | O27: =SUM(I27:N27) -> 141675 | P27: =V26 -> 1762.5 | Q27: 0 | R27: =X26 -> 900 | S27: =Y26 -> 1500 | T27: =Z26 -> 0 | U27: =AB26 -> 4162.5 | V27: =P27+H27 -> 3525 | W27: 0 | X27: =R27+D27 -> 1800 | Y27: =S27+E27 -> 3000 | Z27: =T27+F27 -> 0 | AB27: =SUM(V27:AA27) -> 8325
A28: =A27+1 -> 2027 | B28: =IF(A28=$B$13+$D$16,($B$16*$B$9/$D$16)*(1-$B$14),IF(A28<$B$13+$D$16,$B$16*$B$9/$D$16,0)) -> 1200 | C28: =IF(A28=$B$13+$D$17,($B$17*$B$9/$D$17)*(1-$B$14),IF(A28<$B$13+$D$17,$B$17*$B$9/$D$17,0)) -> 562.5 | D28: =IF(A28=$B$13+$D$18,($B$18*$B$9/$D$18)*(1-$B$14),IF(A28<$B$13+$D$18,$B$18*$B$9/$D$18,0)) -> 900 | E28: =IF(A28=$B$13+$D$19,($B$19*$B$9/$D$19)*(1-$B$14),IF(A28<$B$13+$D$19,$B$19*$B$9/$D$19,0)) -> 1500 | F28: =IF(A28=$B$13+$D$20,($B$20/$D$20)*(1-$B$14),IF(A28<$B$13+$D$20,$B$20/$D$20,0)) -> 0 | G28: =SUM(B28:F28) -> 4162.5 | H28: =B28+C28 -> 1762.5 | I28: =$B$9*($B$16+$B$17)-V28 -> 77212.5 | J28: =$B$9*($B$18)-X28 -> 19800 | K28: =$B$9*($B$19)-Y28 -> 18000 | L28: =$B$20-Z28+AJ28 -> 0 | N28: =$B$9*$B$15 -> 22500 | O28: =SUM(I28:N28) -> 137512.5 | P28: =V27 -> 3525 | Q28: 0 | R28: =X27 -> 1800 | S28: =Y27 -> 3000 | T28: =Z27 -> 0 | U28: =AB27 -> 8325 | V28: =P28+H28 -> 5287.5 | W28: 0 | X28: =R28+D28 -> 2700 | Y28: =S28+E28 -> 4500 | Z28: =T28+F28 -> 0 | AB28: =SUM(V28:AA28) -> 12487.5
A29: =A28+1 -> 2028 | B29: =IF(A29=$B$13+$D$16,($B$16*$B$9/$D$16)*(1-$B$14),IF(A29<$B$13+$D$16,$B$16*$B$9/$D$16,0)) -> 1200 | C29: =IF(A29=$B$13+$D$17,($B$17*$B$9/$D$17)*(1-$B$14),IF(A29<$B$13+$D$17,$B$17*$B$9/$D$17,0)) -> 562.5 | D29: =IF(A29=$B$13+$D$18,($B$18*$B$9/$D$18)*(1-$B$14),IF(A29<$B$13+$D$18,$B$18*$B$9/$D$18,0)) -> 900 | E29: =IF(A29=$B$13+$D$19,($B$19*$B$9/$D$19)*(1-$B$14),IF(A29<$B$13+$D$19,$B$19*$B$9/$D$19,0)) -> 1500 | F29: =IF(A29=$B$13+$D$20,($B$20/$D$20)*(1-$B$14),IF(A29<$B$13+$D$20,$B$20/$D$20,0)) -> 0 | G29: =SUM(B29:F29) -> 4162.5 | H29: =B29+C29 -> 1762.5 | I29: =$B$9*($B$16+$B$17)-V29 -> 75450 | J29: =$B$9*($B$18)-X29 -> 18900 | K29: =$B$9*($B$19)-Y29 -> 16500 | L29: =$B$20-Z29+AJ29 -> 0 | N29: =$B$9*$B$15 -> 22500 | O29: =SUM(I29:N29) -> 133350 | P29: =V28 -> 5287.5 | Q29: 0 | R29: =X28 -> 2700 | S29: =Y28 -> 4500 | T29: =Z28 -> 0 | U29: =AB28 -> 12487.5 | V29: =P29+H29 -> 7050 | W29: 0 | X29: =R29+D29 -> 3600 | Y29: =S29+E29 -> 6000 | Z29: =T29+F29 -> 0 | AB29: =SUM(V29:AA29) -> 16650
A30: =A29+1 -> 2029 | B30: =IF(A30=$B$13+$D$16,($B$16*$B$9/$D$16)*(1-$B$14),IF(A30<$B$13+$D$16,$B$16*$B$9/$D$16,0)) -> 1200 | C30: =IF(A30=$B$13+$D$17,($B$17*$B$9/$D$17)*(1-$B$14),IF(A30<$B$13+$D$17,$B$17*$B$9/$D$17,0)) -> 562.5 | D30: =IF(A30=$B$13+$D$18,($B$18*$B$9/$D$18)*(1-$B$14),IF(A30<$B$13+$D$18,$B$18*$B$9/$D$18,0)) -> 900 | E30: =IF(A30=$B$13+$D$19,($B$19*$B$9/$D$19)*(1-$B$14),IF(A30<$B$13+$D$19,$B$19*$B$9/$D$19,0)) -> 1500 | F30: =IF(A30=$B$13+$D$20,($B$20/$D$20)*(1-$B$14),IF(A30<$B$13+$D$20,$B$20/$D$20,0)) -> 0 | G30: =SUM(B30:F30) -> 4162.5 | H30: =B30+C30 -> 1762.5 | I30: =$B$9*($B$16+$B$17)-V30 -> 73687.5 | J30: =$B$9*($B$18)-X30 -> 18000 | K30: =$B$9*($B$19)-Y30 -> 15000 | L30: =$B$20-Z30+AJ30 -> 0 | N30: =$B$9*$B$15 -> 22500 | O30: =SUM(I30:N30) -> 129187.5 | P30: =V29 -> 7050 | Q30: 0 | R30: =X29 -> 3600 | S30: =Y29 -> 6000 | T30: =Z29 -> 0 | U30: =AB29 -> 16650 | V30: =P30+H30 -> 8812.5 | W30: 0 | X30: =R30+D30 -> 4500 | Y30: =S30+E30 -> 7500 | Z30: =T30+F30 -> 0 | AB30: =SUM(V30:AA30) -> 20812.5
A31: =A30+1 -> 2030 | B31: =IF(A31=$B$13+$D$16,($B$16*$B$9/$D$16)*(1-$B$14),IF(A31<$B$13+$D$16,$B$16*$B$9/$D$16,0)) -> 1200 | C31: =IF(A31=$B$13+$D$17,($B$17*$B$9/$D$17)*(1-$B$14),IF(A31<$B$13+$D$17,$B$17*$B$9/$D$17,0)) -> 562.5 | D31: =IF(A31=$B$13+$D$18,($B$18*$B$9/$D$18)*(1-$B$14),IF(A31<$B$13+$D$18,$B$18*$B$9/$D$18,0)) -> 900 | E31: =IF(A31=$B$13+$D$19,($B$19*$B$9/$D$19)*(1-$B$14),IF(A31<$B$13+$D$19,$B$19*$B$9/$D$19,0)) -> 1500 | F31: =IF(A31=$B$13+$D$20,($B$20/$D$20)*(1-$B$14),IF(A31<$B$13+$D$20,$B$20/$D$20,0)) -> 0 | G31: =SUM(B31:F31) -> 4162.5 | H31: =B31+C31 -> 1762.5 | I31: =$B$9*($B$16+$B$17)-V31 -> 71925 | J31: =$B$9*($B$18)-X31 -> 17100 | K31: =$B$9*($B$19)-Y31 -> 13500 | L31: =$B$20-Z31+AJ31 -> 0 | N31: =$B$9*$B$15 -> 22500 | O31: =SUM(I31:N31) -> 125025 | P31: =V30 -> 8812.5 | Q31: 0 | R31: =X30 -> 4500 | S31: =Y30 -> 7500 | T31: =Z30 -> 0 | U31: =AB30 -> 20812.5 | V31: =P31+H31 -> 10575 | W31: 0 | X31: =R31+D31 -> 5400 | Y31: =S31+E31 -> 9000 | Z31: =T31+F31 -> 0 | AB31: =SUM(V31:AA31) -> 24975
A32: =A31+1 -> 2031 | B32: =IF(A32=$B$13+$D$16,($B$16*$B$9/$D$16)*(1-$B$14),IF(A32<$B$13+$D$16,$B$16*$B$9/$D$16,0)) -> 1200 | C32: =IF(A32=$B$13+$D$17,($B$17*$B$9/$D$17)*(1-$B$14),IF(A32<$B$13+$D$17,$B$17*$B$9/$D$17,0)) -> 562.5 | D32: =IF(A32=$B$13+$D$18,($B$18*$B$9/$D$18)*(1-$B$14),IF(A32<$B$13+$D$18,$B$18*$B$9/$D$18,0)) -> 900 | E32: =IF(A32=$B$13+$D$19,($B$19*$B$9/$D$19)*(1-$B$14),IF(A32<$B$13+$D$19,$B$19*$B$9/$D$19,0)) -> 1500 | F32: =IF(A32=$B$13+$D$20,($B$20/$D$20)*(1-$B$14),IF(A32<$B$13+$D$20,$B$20/$D$20,0)) -> 0 | G32: =SUM(B32:F32) -> 4162.5 | H32: =B32+C32 -> 1762.5 | I32: =$B$9*($B$16+$B$17)-V32 -> 70162.5 | J32: =$B$9*($B$18)-X32 -> 16200 | K32: =$B$9*($B$19)-Y32 -> 12000 | L32: =$B$20-Z32+AJ32 -> 0 | N32: =$B$9*$B$15 -> 22500 | O32: =SUM(I32:N32) -> 120862.5 | P32: =V31 -> 10575 | Q32: 0 | R32: =X31 -> 5400 | S32: =Y31 -> 9000 | T32: =Z31 -> 0 | U32: =AB31 -> 24975 | V32: =P32+H32 -> 12337.5 | W32: 0 | X32: =R32+D32 -> 6300 | Y32: =S32+E32 -> 10500 | Z32: =T32+F32 -> 0 | AB32: =SUM(V32:AA32) -> 29137.5
A33: =A32+1 -> 2032 | B33: =IF(A33=$B$13+$D$16,($B$16*$B$9/$D$16)*(1-$B$14),IF(A33<$B$13+$D$16,$B$16*$B$9/$D$16,0)) -> 1200 | C33: =IF(A33=$B$13+$D$17,($B$17*$B$9/$D$17)*(1-$B$14),IF(A33<$B$13+$D$17,$B$17*$B$9/$D$17,0)) -> 562.5 | D33: =IF(A33=$B$13+$D$18,($B$18*$B$9/$D$18)*(1-$B$14),IF(A33<$B$13+$D$18,$B$18*$B$9/$D$18,0)) -> 900 | E33: =IF(A33=$B$13+$D$19,($B$19*$B$9/$D$19)*(1-$B$14),IF(A33<$B$13+$D$19,$B$19*$B$9/$D$19,0)) -> 1500 | F33: =IF(A33=$B$13+$D$20,($B$20/$D$20)*(1-$B$14),IF(A33<$B$13+$D$20,$B$20/$D$20,0)) -> 0 | G33: =SUM(B33:F33) -> 4162.5 | H33: =B33+C33 -> 1762.5 | I33: =$B$9*($B$16+$B$17)-V33 -> 68400 | J33: =$B$9*($B$18)-X33 -> 15300 | K33: =$B$9*($B$19)-Y33 -> 10500 | L33: =$B$20-Z33+AJ33 -> 0 | N33: =$B$9*$B$15 -> 22500 | O33: =SUM(I33:N33) -> 116700 | P33: =V32 -> 12337.5 | Q33: 0 | R33: =X32 -> 6300 | S33: =Y32 -> 10500 | T33: =Z32 -> 0 | U33: =AB32 -> 29137.5 | V33: =P33+H33 -> 14100 | W33: 0 | X33: =R33+D33 -> 7200 | Y33: =S33+E33 -> 12000 | Z33: =T33+F33 -> 0 | AB33: =SUM(V33:AA33) -> 33300
A34: =A33+1 -> 2033 | B34: =IF(A34=$B$13+$D$16,($B$16*$B$9/$D$16)*(1-$B$14),IF(A34<$B$13+$D$16,$B$16*$B$9/$D$16,0)) -> 1200 | C34: =IF(A34=$B$13+$D$17,($B$17*$B$9/$D$17)*(1-$B$14),IF(A34<$B$13+$D$17,$B$17*$B$9/$D$17,0)) -> 562.5 | D34: =IF(A34=$B$13+$D$18,($B$18*$B$9/$D$18)*(1-$B$14),IF(A34<$B$13+$D$18,$B$18*$B$9/$D$18,0)) -> 900 | E34: =IF(A34=$B$13+$D$19,($B$19*$B$9/$D$19)*(1-$B$14),IF(A34<$B$13+$D$19,$B$19*$B$9/$D$19,0)) -> 1500 | F34: =IF(A34=$B$13+$D$20,($B$20/$D$20)*(1-$B$14),IF(A34<$B$13+$D$20,$B$20/$D$20,0)) -> 0 | G34: =SUM(B34:F34) -> 4162.5 | H34: =B34+C34 -> 1762.5 | I34: =$B$9*($B$16+$B$17)-V34 -> 66637.5 | J34: =$B$9*($B$18)-X34 -> 14400 | K34: =$B$9*($B$19)-Y34 -> 9000 | L34: =$B$20-Z34+AJ34 -> 0 | N34: =$B$9*$B$15 -> 22500 | O34: =SUM(I34:N34) -> 112537.5 | P34: =V33 -> 14100 | Q34: 0 | R34: =X33 -> 7200 | S34: =Y33 -> 12000 | T34: =Z33 -> 0 | U34: =AB33 -> 33300 | V34: =P34+H34 -> 15862.5 | W34: 0 | X34: =R34+D34 -> 8100 | Y34: =S34+E34 -> 13500 | Z34: =T34+F34 -> 0 | AB34: =SUM(V34:AA34) -> 37462.5
A35: =A34+1 -> 2034 | B35: =IF(A35=$B$13+$D$16,($B$16*$B$9/$D$16)*(1-$B$14),IF(A35<$B$13+$D$16,$B$16*$B$9/$D$16,0)) -> 1200 | C35: =IF(A35=$B$13+$D$17,($B$17*$B$9/$D$17)*(1-$B$14),IF(A35<$B$13+$D$17,$B$17*$B$9/$D$17,0)) -> 562.5 | D35: =IF(A35=$B$13+$D$18,($B$18*$B$9/$D$18)*(1-$B$14),IF(A35<$B$13+$D$18,$B$18*$B$9/$D$18,0)) -> 900 | E35: =IF(A35=$B$13+$D$19,($B$19*$B$9/$D$19)*(1-$B$14),IF(A35<$B$13+$D$19,$B$19*$B$9/$D$19,0)) -> 1500 | F35: =IF(A35=$B$13+$D$20,($B$20/$D$20)*(1-$B$14),IF(A35<$B$13+$D$20,$B$20/$D$20,0)) -> 0 | G35: =SUM(B35:F35) -> 4162.5 | H35: =B35+C35 -> 1762.5 | I35: =$B$9*($B$16+$B$17)-V35 -> 64875 | J35: =$B$9*($B$18)-X35 -> 13500 | K35: =$B$9*($B$19)-Y35 -> 7500 | L35: =$B$20-Z35+AJ35 -> 0 | N35: =$B$9*$B$15 -> 22500 | O35: =SUM(I35:N35) -> 108375 | P35: =V34 -> 15862.5 | Q35: 0 | R35: =X34 -> 8100 | S35: =Y34 -> 13500 | T35: =Z34 -> 0 | U35: =AB34 -> 37462.5 | V35: =P35+H35 -> 17625 | W35: 0 | X35: =R35+D35 -> 9000 | Y35: =S35+E35 -> 15000 | Z35: =T35+F35 -> 0 | AB35: =SUM(V35:AA35) -> 41625
A36: =A35+1 -> 2035 | B36: =IF(A36=$B$13+$D$16,($B$16*$B$9/$D$16)*(1-$B$14),IF(A36<$B$13+$D$16,$B$16*$B$9/$D$16,0)) -> 1200 | C36: =IF(A36=$B$13+$D$17,($B$17*$B$9/$D$17)*(1-$B$14),IF(A36<$B$13+$D$17,$B$17*$B$9/$D$17,0)) -> 562.5 | D36: =IF(A36=$B$13+$D$18,($B$18*$B$9/$D$18)*(1-$B$14),IF(A36<$B$13+$D$18,$B$18*$B$9/$D$18,0)) -> 900 | E36: =IF(A36=$B$13+$D$19,($B$19*$B$9/$D$19)*(1-$B$14),IF(A36<$B$13+$D$19,$B$19*$B$9/$D$19,0)) -> 1500 | F36: =IF(A36=$B$13+$D$20,($B$20/$D$20)*(1-$B$14),IF(A36<$B$13+$D$20,$B$20/$D$20,0)) -> 0 | G36: =SUM(B36:F36) -> 4162.5 | H36: =B36+C36 -> 1762.5 | I36: =$B$9*($B$16+$B$17)-V36 -> 63112.5 | J36: =$B$9*($B$18)-X36 -> 12600 | K36: =$B$9*($B$19)-Y36 -> 6000 | L36: =$B$20-Z36+AJ36 -> 0 | N36: =$B$9*$B$15 -> 22500 | O36: =SUM(I36:N36) -> 104212.5 | P36: =V35 -> 17625 | Q36: 0 | R36: =X35 -> 9000 | S36: =Y35 -> 15000 | T36: =Z35 -> 0 | U36: =AB35 -> 41625 | V36: =P36+H36 -> 19387.5 | W36: 0 | X36: =R36+D36 -> 9900 | Y36: =S36+E36 -> 16500 | Z36: =T36+F36 -> 0 | AB36: =SUM(V36:AA36) -> 45787.5
A37: =A36+1 -> 2036 | B37: =IF(A37=$B$13+$D$16,($B$16*$B$9/$D$16)*(1-$B$14),IF(A37<$B$13+$D$16,$B$16*$B$9/$D$16,0)) -> 1200 | C37: =IF(A37=$B$13+$D$17,($B$17*$B$9/$D$17)*(1-$B$14),IF(A37<$B$13+$D$17,$B$17*$B$9/$D$17,0)) -> 562.5 | D37: =IF(A37=$B$13+$D$18,($B$18*$B$9/$D$18)*(1-$B$14),IF(A37<$B$13+$D$18,$B$18*$B$9/$D$18,0)) -> 900 | E37: =IF(A37=$B$13+$D$19,($B$19*$B$9/$D$19)*(1-$B$14),IF(A37<$B$13+$D$19,$B$19*$B$9/$D$19,0)) -> 1500 | F37: =IF(A37=$B$13+$D$20,($B$20/$D$20)*(1-$B$14),IF(A37<$B$13+$D$20,$B$20/$D$20,0)) -> 0 | G37: =SUM(B37:F37) -> 4162.5 | H37: =B37+C37 -> 1762.5 | I37: =$B$9*($B$16+$B$17)-V37 -> 61350 | J37: =$B$9*($B$18)-X37 -> 11700 | K37: =$B$9*($B$19)-Y37 -> 4500 | L37: =$B$20-Z37+AJ37 -> 0 | N37: =$B$9*$B$15 -> 22500 | O37: =SUM(I37:N37) -> 100050 | P37: =V36 -> 19387.5 | Q37: 0 | R37: =X36 -> 9900 | S37: =Y36 -> 16500 | T37: =Z36 -> 0 | U37: =AB36 -> 45787.5 | V37: =P37+H37 -> 21150 | W37: 0 | X37: =R37+D37 -> 10800 | Y37: =S37+E37 -> 18000 | Z37: =T37+F37 -> 0 | AB37: =SUM(V37:AA37) -> 49950
A38: =A37+1 -> 2037 | B38: =IF(A38=$B$13+$D$16,($B$16*$B$9/$D$16)*(1-$B$14),IF(A38<$B$13+$D$16,$B$16*$B$9/$D$16,0)) -> 1200 | C38: =IF(A38=$B$13+$D$17,($B$17*$B$9/$D$17)*(1-$B$14),IF(A38<$B$13+$D$17,$B$17*$B$9/$D$17,0)) -> 562.5 | D38: =IF(A38=$B$13+$D$18,($B$18*$B$9/$D$18)*(1-$B$14),IF(A38<$B$13+$D$18,$B$18*$B$9/$D$18,0)) -> 900 | E38: =IF(A38=$B$13+$D$19,($B$19*$B$9/$D$19)*(1-$B$14),IF(A38<$B$13+$D$19,$B$19*$B$9/$D$19,0)) -> 1500 | F38: =IF(A38=$B$13+$D$20,($B$20/$D$20)*(1-$B$14),IF(A38<$B$13+$D$20,$B$20/$D$20,0)) -> 0 | G38: =SUM(B38:F38) -> 4162.5 | H38: =B38+C38 -> 1762.5 | I38: =$B$9*($B$16+$B$17)-V38 -> 59587.5 | J38: =$B$9*($B$18)-X38 -> 10800 | K38: =$B$9*($B$19)-Y38 -> 3000 | L38: =$B$20-Z38+AJ38 -> 0 | N38: =$B$9*$B$15 -> 22500 | O38: =SUM(I38:N38) -> 95887.5 | P38: =V37 -> 21150 | Q38: 0 | R38: =X37 -> 10800 | S38: =Y37 -> 18000 | T38: =Z37 -> 0 | U38: =AB37 -> 49950 | V38: =P38+H38 -> 22912.5 | W38: 0 | X38: =R38+D38 -> 11700 | Y38: =S38+E38 -> 19500 | Z38: =T38+F38 -> 0 | AB38: =SUM(V38:AA38) -> 54112.5
A39: =A38+1 -> 2038 | B39: =IF(A39=$B$13+$D$16,($B$16*$B$9/$D$16)*(1-$B$14),IF(A39<$B$13+$D$16,$B$16*$B$9/$D$16,0)) -> 1200 | C39: =IF(A39=$B$13+$D$17,($B$17*$B$9/$D$17)*(1-$B$14),IF(A39<$B$13+$D$17,$B$17*$B$9/$D$17,0)) -> 562.5 | D39: =IF(A39=$B$13+$D$18,($B$18*$B$9/$D$18)*(1-$B$14),IF(A39<$B$13+$D$18,$B$18*$B$9/$D$18,0)) -> 900 | E39: =IF(A39=$B$13+$D$19,($B$19*$B$9/$D$19)*(1-$B$14),IF(A39<$B$13+$D$19,$B$19*$B$9/$D$19,0)) -> 1500 | F39: =IF(A39=$B$13+$D$20,($B$20/$D$20)*(1-$B$14),IF(A39<$B$13+$D$20,$B$20/$D$20,0)) -> 0 | G39: =SUM(B39:F39) -> 4162.5 | H39: =B39+C39 -> 1762.5 | I39: =$B$9*($B$16+$B$17)-V39 -> 57825 | J39: =$B$9*($B$18)-X39 -> 9900 | K39: =$B$9*($B$19)-Y39 -> 1500 | L39: =$B$20-Z39+AJ39 -> 0 | N39: =$B$9*$B$15 -> 22500 | O39: =SUM(I39:N39) -> 91725 | P39: =V38 -> 22912.5 | Q39: 0 | R39: =X38 -> 11700 | S39: =Y38 -> 19500 | T39: =Z38 -> 0 | U39: =AB38 -> 54112.5 | V39: =P39+H39 -> 24675 | W39: 0 | X39: =R39+D39 -> 12600 | Y39: =S39+E39 -> 21000 | Z39: =T39+F39 -> 0 | AB39: =SUM(V39:AA39) -> 58275
... A76: =A75+1 -> 2075 | B76: =IF(A76=$B$13+$D$16,($B$16*$B$9/$D$16)*(1-$B$14),IF(A76<$B$13+$D$16,$B$16*$B$9/$D$16,0)) -> 0 | C76: =IF(A76=$B$13+$D$17,($B$17*$B$9/$D$17)*(1-$B$14),IF(A76<$B$13+$D$17,$B$17*$B$9/$D$17,0)) -> 0 | D76: =IF(A76=$B$13+$D$18,($B$18*$B$9/$D$18)*(1-$B$14),IF(A76<$B$13+$D$18,$B$18*$B$9/$D$18,0)) -> 0 | E76: =IF(A76=$B$13+$D$19,($B$19*$B$9/$D$19)*(1-$B$14),IF(A76<$B$13+$D$19,$B$19*$B$9/$D$19,0)) -> 0 | F76: =IF(A76=$B$13+$D$20,($B$20/$D$20)*(1-$B$14),IF(A76<$B$13+$D$20,$B$20/$D$20,0)) -> 0 | G76: =SUM(B76:F76) -> 0 | H76: =B76+C76 -> 0 | I76: =$B$9*($B$16+$B$17)-V76 -> 0 | J76: =$B$9*($B$18)-X76 -> 0 | K76: =$B$9*($B$19)-Y76 -> 0 | L76: =$B$20-Z76+AJ76 -> 0 | N76: =$B$9*$B$15 -> 22500 | O76: =SUM(I76:N76) -> 22500 | P76: =V75 -> 82500 | Q76: 0 | R76: =X75 -> 22500 | S76: =Y75 -> 22500 | T76: =Z75 -> 0 | U76: =AB75 -> 127500 | V76: =P76+H76 -> 82500 | W76: 0 | X76: =R76+D76 -> 22500 | Y76: =S76+E76 -> 22500 | Z76: =T76+F76 -> 0 | AB76: =SUM(V76:AA76) -> 127500
A80: ETAPE 3 : Compte de resultat
A82: Année | B82: =F13 -> 2025 | D82: Année | E82: =F13+1 -> 2026
A83: Dotation aux ammortissements (année en cours) | B83: {=INDIRECT(ADDRESS(H13,7))} -> 4162.5 | D83: Dotation aux ammortissements (année en cours) | E83: {=INDIRECT(ADDRESS(H13+1,7))} -> 4162.5
...

Sheet Appartement 2
A1: Etape 1 prix de départ Appartement 2: | D1: Espace Pro : impot gouv : Déclarer : Résultat
A4: Prix d'achat | B4: 150000
A5: Frais de notaire | B5: =0 -> 0
A6: frais d'agence | B6: =0 -> 0
A7: Mobilier | B7: =0 -> 0
A8: Travaux à amortir | B8: =0 -> 0
A9: Base amortissable | B9: =IF(B4>0,SUM(B4:B6),IF(E4>0,E4,0)) -> 150000
A11: Etape 2 : Décomposition et amortissement
A12: Date de début d'activité | B12: 45658
A13: Année de début d'activité | B13: =YEAR(B12) -> 2025 | E13: Année d'exercice | F13: =YEAR(TODAY())-1 -> 2025 | H13: =F13-B13+26 -> 26
A14: Prorata | B14: =YEARFRAC(B12,DATE(YEAR(B12)+1,1,1),4) -> 1 | AD14: Travaux/Mobilier | AE14: Montant | AF14: Date debut | AG14: Nbr année amortissement | AH14: Prorata première année
A15: Terrain | B15: =15% -> 0.15 | AD15: Travaux/Mobilier 1 | AE15: 0 | AF15: 45809 | AG15: 10 | AH15: =YEARFRAC(AF15,DATE(YEAR(AF15)+1,1,1),4) -> 0.58333333
A16: Structure (Gros oeuvre) | B16: =40% -> 0.4 | C16: du total sur | D16: 50 | E16: ans | AD16: Travaux/Mobilier 2 | AE16: 0 | AF16: 46174 | AG16: 10 | AH16: =YEARFRAC(AF16,DATE(YEAR(AF16)+1,1,1),4) -> 0.58333333
A17: Façade, étanchieté | B17: =15% -> 0.15 | C17: du total sur | D17: 40 | E17: ans | AD17: Travaux/Mobilier 3 | AE17: 0 | AF17: 46539 | AG17: 10 | AH17: =YEARFRAC(AF17,DATE(YEAR(AF17)+1,1,1),4) -> 0.58333333
A18: IGT, Equipement | B18: =15% -> 0.15 | C18: du total sur | D18: 25 | E18: ans | AD18: Travaux/Mobilier 4 | AE18: 0 | AF18: 46905 | AG18: 10 | AH18: =YEARFRAC(AF18,DATE(YEAR(AF18)+1,1,1),4) -> 0.58333333
A19: Agencements (cloisons, chapes, platerie, revetement, plomberie, cablage) | B19: =15% -> 0.15 | C19: du total sur | D19: 15 | E19: ans | AD19: Travaux/Mobilier 5 | AE19: 0 | AF19: 47270 | AG19: 10 | AH19: =YEARFRAC(AF19,DATE(YEAR(AF19)+1,1,1),4) -> 0.58333333
A20: Mobilier+travaux avant 1ere location | B20: =B7+B8 -> 0 | D20: 10 | E20: ans | AD20: Travaux/Mobilier 6 | AE20: 0 | AF20: 47635 | AG20: 10 | AH20: =YEARFRAC(AF20,DATE(YEAR(AF20)+1,1,1),4) -> 0.58333333
A21: Frais de notaire | B21: =B5 -> 0 | D21: 0 | AD21: Travaux/Mobilier 7 | AE21: 0 | AF21: 48000 | AG21: 10 | AH21: =YEARFRAC(AF21,DATE(YEAR(AF21)+1,1,1),4) -> 0.58333333
A22: Frais d'agence | B22: =B6 -> 0 | D22: 0 | AD22: Travaux/Mobilier 8 | AE22: 0 | AF22: 48000 | AG22: 10 | AH22: =YEARFRAC(AF22,DATE(YEAR(AF22)+1,1,1),4) -> 0.58333333
AD23: Travaux/Mobilier 9 | AE23: 0 | AF23: 48000 | AG23: 10 | AH23: =YEARFRAC(AF23,DATE(YEAR(AF23)+1,1,1),4) -> 0.58333333
C24: Augmentation Amortissement (dotations) | K24: Immobilisations net | Q24: Ammortissement début d'excercice | W24: Ammortissement fin exercice | AD24: Travaux/Mobilier 10 | AE24: 0 | AF24: 48000 | AG24: 10 | AH24: =YEARFRAC(AF24,DATE(YEAR(AF24)+1,1,1),4) -> 0.58333333
A25: Année | B25: Structure | C25: Façade | D25: Equipement | E25: Agencement | F25: Autres immobilisations corporelles | G25: Total Ammortissement | H25: Construction | I25: Construction | J25: Immo equipement | K25: Immo agencement | L25: Autres immobilisations corporelles | N25: Terrain | O25: Total | P25: Construction | Q25: Terrain | R25: Equipement | S25: Agencement | T25: Autres immobilisations corporelles | U25: Total | V25: Construction | W25: Terrain | X25: Equipement | Y25: Agencement | Z25: Autres immobilisations corporelles | AB25: Total
A26: 2025 | B26: =IF(A26<$B$13+$D$16,$B$16*$B$9/$D$16,0)*B14 -> 1200 | C26: =IF(A26<$B$13+$D17,$B$17*$B$9/$D$17,0)*B14 -> 562.5 | D26: =IF(A26<$B$13+$D18,$B$18*$B$9/$D$18,0)*B14 -> 900 | E26: =IF(A26<$B$13+$D$19,$B$19*$B$9/$D$19,0)*B14 -> 1500 | F26: =(IF(A26<$B$13+$D$20,$B$20/$D$20,0)*B14) -> 0 | G26: =SUM(B26:F26) -> 4162.5 | H26: =B26+C26 -> 1762.5 | I26: =$B$9*($B$16+$B$17)-V26 -> 80737.5 | J26: =$B$9*($B$18)-X26 -> 21600 | K26: =$B$9*($B$19)-Y26 -> 21000 | L26: =$B$20-Z26+AJ26 -> 0 | N26: =$B$9*$B$15 -> 22500 | O26: =SUM(I26:N26) -> 145837.5 | P26: 0 | Q26: 0 | R26: 0 | S26: 0 | T26: 0 | U26: 0 | V26: =P26+H26 -> 1762.5 | W26: 0 | X26: =R26+D26 -> 900 | Y26: =S26+E26 -> 1500 | Z26: =T26+F26 -> 0 | AB26: =SUM(V26:AA26) -> 4162.5
A27: 2026 | B27: =IF(A27=$B$13+$D$16,($B$16*$B$9/$D$16)*(1-$B$14),IF(A27<$B$13+$D$16,$B$16*$B$9/$D$16,0)) -> 1200 | C27: =IF(A27=$B$13+$D$17,($B$17*$B$9/$D$17)*(1-$B$14),IF(A27<$B$13+$D$17,$B$17*$B$9/$D$17,0)) -> 562.5 | D27: =IF(A27=$B$13+$D$18,($B$18*$B$9/$D$18)*(1-$B$14),IF(A27<$B$13+$D$18,$B$18*$B$9/$D$18,0)) -> 900 | E27: =IF(A27=$B$13+$D$19,($B$19*$B$9/$D$19)*(1-$B$14),IF(A27<$B$13+$D$19,$B$19*$B$9/$D$19,0)) -> 1500 | F27: =IF(A27=$B$13+$D$20,($B$20/$D$20)*(1-$B$14),IF(A27<$B$13+$D$20,$B$20/$D$20,0)) -> 0 | G27: =SUM(B27:F27) -> 4162.5 | H27: =B27+C27 -> 1762.5 | I27: =$B$9*($B$16+$B$17)-V27 -> 78975 | J27: =$B$9*($B$18)-X27 -> 20700 | K27: =$B$9*($B$19)-Y27 -> 19500 | L27: =$B$20-Z27+AJ27 -> 0 | N27: =$B$9*$B$15 -> 22500 | O27: =SUM(I27:N27) -> 141675 | P27: =V26 -> 1762.5 | Q27: 0 | R27: =X26 -> 900 | S27: =Y26 -> 1500 | T27: =Z26 -> 0 | U27: =AB26 -> 4162.5 | V27: =P27+H27 -> 3525 | W27: 0 | X27: =R27+D27 -> 1800 | Y27: =S27+E27 -> 3000 | Z27: =T27+F27 -> 0 | AB27: =SUM(V27:AA27) -> 8325
A28: =A27+1 -> 2027 | B28: =IF(A28=$B$13+$D$16,($B$16*$B$9/$D$16)*(1-$B$14),IF(A28<$B$13+$D$16,$B$16*$B$9/$D$16,0)) -> 1200 | C28: =IF(A28=$B$13+$D$17,($B$17*$B$9/$D$17)*(1-$B$14),IF(A28<$B$13+$D$17,$B$17*$B$9/$D$17,0)) -> 562.5 | D28: =IF(A28=$B$13+$D$18,($B$18*$B$9/$D$18)*(1-$B$14),IF(A28<$B$13+$D$18,$B$18*$B$9/$D$18,0)) -> 900 | E28: =IF(A28=$B$13+$D$19,($B$19*$B$9/$D$19)*(1-$B$14),IF(A28<$B$13+$D$19,$B$19*$B$9/$D$19,0)) -> 1500 | F28: =IF(A28=$B$13+$D$20,($B$20/$D$20)*(1-$B$14),IF(A28<$B$13+$D$20,$B$20/$D$20,0)) -> 0 | G28: =SUM(B28:F28) -> 4162.5 | H28: =B28+C28 -> 1762.5 | I28: =$B$9*($B$16+$B$17)-V28 -> 77212.5 | J28: =$B$9*($B$18)-X28 -> 19800 | K28: =$B$9*($B$19)-Y28 -> 18000 | L28: =$B$20-Z28+AJ28 -> 0 | N28: =$B$9*$B$15 -> 22500 | O28: =SUM(I28:N28) -> 137512.5 | P28: =V27 -> 3525 | Q28: 0 | R28: =X27 -> 1800 | S28: =Y27 -> 3000 | T28: =Z27 -> 0 | U28: =AB27 -> 8325 | V28: =P28+H28 -> 5287.5 | W28: 0 | X28: =R28+D28 -> 2700 | Y28: =S28+E28 -> 4500 | Z28: =T28+F28 -> 0 | AB28: =SUM(V28:AA28) -> 12487.5
A29: =A28+1 -> 2028 | B29: =IF(A29=$B$13+$D$16,($B$16*$B$9/$D$16)*(1-$B$14),IF(A29<$B$13+$D$16,$B$16*$B$9/$D$16,0)) -> 1200 | C29: =IF(A29=$B$13+$D$17,($B$17*$B$9/$D$17)*(1-$B$14),IF(A29<$B$13+$D$17,$B$17*$B$9/$D$17,0)) -> 562.5 | D29: =IF(A29=$B$13+$D$18,($B$18*$B$9/$D$18)*(1-$B$14),IF(A29<$B$13+$D$18,$B$18*$B$9/$D$18,0)) -> 900 | E29: =IF(A29=$B$13+$D$19,($B$19*$B$9/$D$19)*(1-$B$14),IF(A29<$B$13+$D$19,$B$19*$B$9/$D$19,0)) -> 1500 | F29: =IF(A29=$B$13+$D$20,($B$20/$D$20)*(1-$B$14),IF(A29<$B$13+$D$20,$B$20/$D$20,0)) -> 0 | G29: =SUM(B29:F29) -> 4162.5 | H29: =B29+C29 -> 1762.5 | I29: =$B$9*($B$16+$B$17)-V29 -> 75450 | J29: =$B$9*($B$18)-X29 -> 18900 | K29: =$B$9*($B$19)-Y29 -> 16500 | L29: =$B$20-Z29+AJ29 -> 0 | N29: =$B$9*$B$15 -> 22500 | O29: =SUM(I29:N29) -> 133350 | P29: =V28 -> 5287.5 | Q29: 0 | R29: =X28 -> 2700 | S29: =Y28 -> 4500 | T29: =Z28 -> 0 | U29: =AB28 -> 12487.5 | V29: =P29+H29 -> 7050 | W29: 0 | X29: =R29+D29 -> 3600 | Y29: =S29+E29 -> 6000 | Z29: =T29+F29 -> 0 | AB29: =SUM(V29:AA29) -> 16650
A30: =A29+1 -> 2029 | B30: =IF(A30=$B$13+$D$16,($B$16*$B$9/$D$16)*(1-$B$14),IF(A30<$B$13+$D$16,$B$16*$B$9/$D$16,0)) -> 1200 | C30: =IF(A30=$B$13+$D$17,($B$17*$B$9/$D$17)*(1-$B$14),IF(A30<$B$13+$D$17,$B$17*$B$9/$D$17,0)) -> 562.5 | D30: =IF(A30=$B$13+$D$18,($B$18*$B$9/$D$18)*(1-$B$14),IF(A30<$B$13+$D$18,$B$18*$B$9/$D$18,0)) -> 900 | E30: =IF(A30=$B$13+$D$19,($B$19*$B$9/$D$19)*(1-$B$14),IF(A30<$B$13+$D$19,$B$19*$B$9/$D$19,0)) -> 1500 | F30: =IF(A30=$B$13+$D$20,($B$20/$D$20)*(1-$B$14),IF(A30<$B$13+$D$20,$B$20/$D$20,0)) -> 0 | G30: =SUM(B30:F30) -> 4162.5 | H30: =B30+C30 -> 1762.5 | I30: =$B$9*($B$16+$B$17)-V30 -> 73687.5 | J30: =$B$9*($B$18)-X30 -> 18000 | K30: =$B$9*($B$19)-Y30 -> 15000 | L30: =$B$20-Z30+AJ30 -> 0 | N30: =$B$9*$B$15 -> 22500 | O30: =SUM(I30:N30) -> 129187.5 | P30: =V29 -> 7050 | Q30: 0 | R30: =X29 -> 3600 | S30: =Y29 -> 6000 | T30: =Z29 -> 0 | U30: =AB29 -> 16650 | V30: =P30+H30 -> 8812.5 | W30: 0 | X30: =R30+D30 -> 4500 | Y30: =S30+E30 -> 7500 | Z30: =T30+F30 -> 0 | AB30: =SUM(V30:AA30) -> 20812.5
A31: =A30+1 -> 2030 | B31: =IF(A31=$B$13+$D$16,($B$16*$B$9/$D$16)*(1-$B$14),IF(A31<$B$13+$D$16,$B$16*$B$9/$D$16,0)) -> 1200 | C31: =IF(A31=$B$13+$D$17,($B$17*$B$9/$D$17)*(1-$B$14),IF(A31<$B$13+$D$17,$B$17*$B$9/$D$17,0)) -> 562.5 | D31: =IF(A31=$B$13+$D$18,($B$18*$B$9/$D$18)*(1-$B$14),IF(A31<$B$13+$D$18,$B$18*$B$9/$D$18,0)) -> 900 | E31: =IF(A31=$B$13+$D$19,($B$19*$B$9/$D$19)*(1-$B$14),IF(A31<$B$13+$D$19,$B$19*$B$9/$D$19,0)) -> 1500 | F31: =IF(A31=$B$13+$D$20,($B$20/$D$20)*(1-$B$14),IF(A31<$B$13+$D$20,$B$20/$D$20,0)) -> 0 | G31: =SUM(B31:F31) -> 4162.5 | H31: =B31+C31 -> 1762.5 | I31: =$B$9*($B$16+$B$17)-V31 -> 71925 | J31: =$B$9*($B$18)-X31 -> 17100 | K31: =$B$9*($B$19)-Y31 -> 13500 | L31: =$B$20-Z31+AJ31 -> 0 | N31: =$B$9*$B$15 -> 22500 | O31: =SUM(I31:N31) -> 125025 | P31: =V30 -> 8812.5 | Q31: 0 | R31: =X30 -> 4500 | S31: =Y30 -> 7500 | T31: =Z30 -> 0 | U31: =AB30 -> 20812.5 | V31: =P31+H31 -> 10575 | W31: 0 | X31: =R31+D31 -> 5400 | Y31: =S31+E31 -> 9000 | Z31: =T31+F31 -> 0 | AB31: =SUM(V31:AA31) -> 24975
A32: =A31+1 -> 2031 | B32: =IF(A32=$B$13+$D$16,($B$16*$B$9/$D$16)*(1-$B$14),IF(A32<$B$13+$D$16,$B$16*$B$9/$D$16,0)) -> 1200 | C32: =IF(A32=$B$13+$D$17,($B$17*$B$9/$D$17)*(1-$B$14),IF(A32<$B$13+$D$17,$B$17*$B$9/$D$17,0)) -> 562.5 | D32: =IF(A32=$B$13+$D$18,($B$18*$B$9/$D$18)*(1-$B$14),IF(A32<$B$13+$D$18,$B$18*$B$9/$D$18,0)) -> 900 | E32: =IF(A32=$B$13+$D$19,($B$19*$B$9/$D$19)*(1-$B$14),IF(A32<$B$13+$D$19,$B$19*$B$9/$D$19,0)) -> 1500 | F32: =IF(A32=$B$13+$D$20,($B$20/$D$20)*(1-$B$14),IF(A32<$B$13+$D$20,$B$20/$D$20,0)) -> 0 | G32: =SUM(B32:F32) -> 4162.5 | H32: =B32+C32 -> 1762.5 | I32: =$B$9*($B$16+$B$17)-V32 -> 70162.5 | J32: =$B$9*($B$18)-X32 -> 16200 | K32: =$B$9*($B$19)-Y32 -> 12000 | L32: =$B$20-Z32+AJ32 -> 0 | N32: =$B$9*$B$15 -> 22500 | O32: =SUM(I32:N32) -> 120862.5 | P32: =V31 -> 10575 | Q32: 0 | R32: =X31 -> 5400 | S32: =Y31 -> 9000 | T32: =Z31 -> 0 | U32: =AB31 -> 24975 | V32: =P32+H32 -> 12337.5 | W32: 0 | X32: =R32+D32 -> 6300 | Y32: =S32+E32 -> 10500 | Z32: =T32+F32 -> 0 | AB32: =SUM(V32:AA32) -> 29137.5
A33: =A32+1 -> 2032 | B33: =IF(A33=$B$13+$D$16,($B$16*$B$9/$D$16)*(1-$B$14),IF(A33<$B$13+$D$16,$B$16*$B$9/$D$16,0)) -> 1200 | C33: =IF(A33=$B$13+$D$17,($B$17*$B$9/$D$17)*(1-$B$14),IF(A33<$B$13+$D$17,$B$17*$B$9/$D$17,0)) -> 562.5 | D33: =IF(A33=$B$13+$D$18,($B$18*$B$9/$D$18)*(1-$B$14),IF(A33<$B$13+$D$18,$B$18*$B$9/$D$18,0)) -> 900 | E33: =IF(A33=$B$13+$D$19,($B$19*$B$9/$D$19)*(1-$B$14),IF(A33<$B$13+$D$19,$B$19*$B$9/$D$19,0)) -> 1500 | F33: =IF(A33=$B$13+$D$20,($B$20/$D$20)*(1-$B$14),IF(A33<$B$13+$D$20,$B$20/$D$20,0)) -> 0 | G33: =SUM(B33:F33) -> 4162.5 | H33: =B33+C33 -> 1762.5 | I33: =$B$9*($B$16+$B$17)-V33 -> 68400 | J33: =$B$9*($B$18)-X33 -> 15300 | K33: =$B$9*($B$19)-Y33 -> 10500 | L33: =$B$20-Z33+AJ33 -> 0 | N33: =$B$9*$B$15 -> 22500 | O33: =SUM(I33:N33) -> 116700 | P33: =V32 -> 12337.5 | Q33: 0 | R33: =X32 -> 6300 | S33: =Y32 -> 10500 | T33: =Z32 -> 0 | U33: =AB32 -> 29137.5 | V33: =P33+H33 -> 14100 | W33: 0 | X33: =R33+D33 -> 7200 | Y33: =S33+E33 -> 12000 | Z33: =T33+F33 -> 0 | AB33: =SUM(V33:AA33) -> 33300
A34: =A33+1 -> 2033 | B34: =IF(A34=$B$13+$D$16,($B$16*$B$9/$D$16)*(1-$B$14),IF(A34<$B$13+$D$16,$B$16*$B$9/$D$16,0)) -> 1200 | C34: =IF(A34=$B$13+$D$17,($B$17*$B$9/$D$17)*(1-$B$14),IF(A34<$B$13+$D$17,$B$17*$B$9/$D$17,0)) -> 562.5 | D34: =IF(A34=$B$13+$D$18,($B$18*$B$9/$D$18)*(1-$B$14),IF(A34<$B$13+$D$18,$B$18*$B$9/$D$18,0)) -> 900 | E34: =IF(A34=$B$13+$D$19,($B$19*$B$9/$D$19)*(1-$B$14),IF(A34<$B$13+$D$19,$B$19*$B$9/$D$19,0)) -> 1500 | F34: =IF(A34=$B$13+$D$20,($B$20/$D$20)*(1-$B$14),IF(A34<$B$13+$D$20,$B$20/$D$20,0)) -> 0 | G34: =SUM(B34:F34) -> 4162.5 | H34: =B34+C34 -> 1762.5 | I34: =$B$9*($B$16+$B$17)-V34 -> 66637.5 | J34: =$B$9*($B$18)-X34 -> 14400 | K34: =$B$9*($B$19)-Y34 -> 9000 | L34: =$B$20-Z34+AJ34 -> 0 | N34: =$B$9*$B$15 -> 22500 | O34: =SUM(I34:N34) -> 112537.5 | P34: =V33 -> 14100 | Q34: 0 | R34: =X33 -> 7200 | S34: =Y33 -> 12000 | T34: =Z33 -> 0 | U34: =AB33 -> 33300 | V34: =P34+H34 -> 15862.5 | W34: 0 | X34: =R34+D34 -> 8100 | Y34: =S34+E34 -> 13500 | Z34: =T34+F34 -> 0 | AB34: =SUM(V34:AA34) -> 37462.5
A35: =A34+1 -> 2034 | B35: =IF(A35=$B$13+$D$16,($B$16*$B$9/$D$16)*(1-$B$14),IF(A35<$B$13+$D$16,$B$16*$B$9/$D$16,0)) -> 1200 | C35: =IF(A35=$B$13+$D$17,($B$17*$B$9/$D$17)*(1-$B$14),IF(A35<$B$13+$D$17,$B$17*$B$9/$D$17,0)) -> 562.5 | D35: =IF(A35=$B$13+$D$18,($B$18*$B$9/$D$18)*(1-$B$14),IF(A35<$B$13+$D$18,$B$18*$B$9/$D$18,0)) -> 900 | E35: =IF(A35=$B$13+$D$19,($B$19*$B$9/$D$19)*(1-$B$14),IF(A35<$B$13+$D$19,$B$19*$B$9/$D$19,0)) -> 1500 | F35: =IF(A35=$B$13+$D$20,($B$20/$D$20)*(1-$B$14),IF(A35<$B$13+$D$20,$B$20/$D$20,0)) -> 0 | G35: =SUM(B35:F35) -> 4162.5 | H35: =B35+C35 -> 1762.5 | I35: =$B$9*($B$16+$B$17)-V35 -> 64875 | J35: =$B$9*($B$18)-X35 -> 13500 | K35: =$B$9*($B$19)-Y35 -> 7500 | L35: =$B$20-Z35+AJ35 -> 0 | N35: =$B$9*$B$15 -> 22500 | O35: =SUM(I35:N35) -> 108375 | P35: =V34 -> 15862.5 | Q35: 0 | R35: =X34 -> 8100 | S35: =Y34 -> 13500 | T35: =Z34 -> 0 | U35: =AB34 -> 37462.5 | V35: =P35+H35 -> 17625 | W35: 0 | X35: =R35+D35 -> 9000 | Y35: =S35+E35 -> 15000 | Z35: =T35+F35 -> 0 | AB35: =SUM(V35:AA35) -> 41625
A36: =A35+1 -> 2035 | B36: =IF(A36=$B$13+$D$16,($B$16*$B$9/$D$16)*(1-$B$14),IF(A36<$B$13+$D$16,$B$16*$B$9/$D$16,0)) -> 1200 | C36: =IF(A36=$B$13+$D$17,($B$17*$B$9/$D$17)*(1-$B$14),IF(A36<$B$13+$D$17,$B$17*$B$9/$D$17,0)) -> 562.5 | D36: =IF(A36=$B$13+$D$18,($B$18*$B$9/$D$18)*(1-$B$14),IF(A36<$B$13+$D$18,$B$18*$B$9/$D$18,0)) -> 900 | E36: =IF(A36=$B$13+$D$19,($B$19*$B$9/$D$19)*(1-$B$14),IF(A36<$B$13+$D$19,$B$19*$B$9/$D$19,0)) -> 1500 | F36: =IF(A36=$B$13+$D$20,($B$20/$D$20)*(1-$B$14),IF(A36<$B$13+$D$20,$B$20/$D$20,0)) -> 0 | G36: =SUM(B36:F36) -> 4162.5 | H36: =B36+C36 -> 1762.5 | I36: =$B$9*($B$16+$B$17)-V36 -> 63112.5 | J36: =$B$9*($B$18)-X36 -> 12600 | K36: =$B$9*($B$19)-Y36 -> 6000 | L36: =$B$20-Z36+AJ36 -> 0 | N36: =$B$9*$B$15 -> 22500 | O36: =SUM(I36:N36) -> 104212.5 | P36: =V35 -> 17625 | Q36: 0 | R36: =X35 -> 9000 | S36: =Y35 -> 15000 | T36: =Z35 -> 0 | U36: =AB35 -> 41625 | V36: =P36+H36 -> 19387.5 | W36: 0 | X36: =R36+D36 -> 9900 | Y36: =S36+E36 -> 16500 | Z36: =T36+F36 -> 0 | AB36: =SUM(V36:AA36) -> 45787.5
A37: =A36+1 -> 2036 | B37: =IF(A37=$B$13+$D$16,($B$16*$B$9/$D$16)*(1-$B$14),IF(A37<$B$13+$D$16,$B$16*$B$9/$D$16,0)) -> 1200 | C37: =IF(A37=$B$13+$D$17,($B$17*$B$9/$D$17)*(1-$B$14),IF(A37<$B$13+$D$17,$B$17*$B$9/$D$17,0)) -> 562.5 | D37: =IF(A37=$B$13+$D$18,($B$18*$B$9/$D$18)*(1-$B$14),IF(A37<$B$13+$D$18,$B$18*$B$9/$D$18,0)) -> 900 | E37: =IF(A37=$B$13+$D$19,($B$19*$B$9/$D$19)*(1-$B$14),IF(A37<$B$13+$D$19,$B$19*$B$9/$D$19,0)) -> 1500 | F37: =IF(A37=$B$13+$D$20,($B$20/$D$20)*(1-$B$14),IF(A37<$B$13+$D$20,$B$20/$D$20,0)) -> 0 | G37: =SUM(B37:F37) -> 4162.5 | H37: =B37+C37 -> 1762.5 | I37: =$B$9*($B$16+$B$17)-V37 -> 61350 | J37: =$B$9*($B$18)-X37 -> 11700 | K37: =$B$9*($B$19)-Y37 -> 4500 | L37: =$B$20-Z37+AJ37 -> 0 | N37: =$B$9*$B$15 -> 22500 | O37: =SUM(I37:N37) -> 100050 | P37: =V36 -> 19387.5 | Q37: 0 | R37: =X36 -> 9900 | S37: =Y36 -> 16500 | T37: =Z36 -> 0 | U37: =AB36 -> 45787.5 | V37: =P37+H37 -> 21150 | W37: 0 | X37: =R37+D37 -> 10800 | Y37: =S37+E37 -> 18000 | Z37: =T37+F37 -> 0 | AB37: =SUM(V37:AA37) -> 49950
A38: =A37+1 -> 2037 | B38: =IF(A38=$B$13+$D$16,($B$16*$B$9/$D$16)*(1-$B$14),IF(A38<$B$13+$D$16,$B$16*$B$9/$D$16,0)) -> 1200 | C38: =IF(A38=$B$13+$D$17,($B$17*$B$9/$D$17)*(1-$B$14),IF(A38<$B$13+$D$17,$B$17*$B$9/$D$17,0)) -> 562.5 | D38: =IF(A38=$B$13+$D$18,($B$18*$B$9/$D$18)*(1-$B$14),IF(A38<$B$13+$D$18,$B$18*$B$9/$D$18,0)) -> 900 | E38: =IF(A38=$B$13+$D$19,($B$19*$B$9/$D$19)*(1-$B$14),IF(A38<$B$13+$D$19,$B$19*$B$9/$D$19,0)) -> 1500 | F38: =IF(A38=$B$13+$D$20,($B$20/$D$20)*(1-$B$14),IF(A38<$B$13+$D$20,$B$20/$D$20,0)) -> 0 | G38: =SUM(B38:F38) -> 4162.5 | H38: =B38+C38 -> 1762.5 | I38: =$B$9*($B$16+$B$17)-V38 -> 59587.5 | J38: =$B$9*($B$18)-X38 -> 10800 | K38: =$B$9*($B$19)-Y38 -> 3000 | L38: =$B$20-Z38+AJ38 -> 0 | N38: =$B$9*$B$15 -> 22500 | O38: =SUM(I38:N38) -> 95887.5 | P38: =V37 -> 21150 | Q38: 0 | R38: =X37 -> 10800 | S38: =Y37 -> 18000 | T38: =Z37 -> 0 | U38: =AB37 -> 49950 | V38: =P38+H38 -> 22912.5 | W38: 0 | X38: =R38+D38 -> 11700 | Y38: =S38+E38 -> 19500 | Z38: =T38+F38 -> 0 | AB38: =SUM(V38:AA38) -> 54112.5
A39: =A38+1 -> 2038 | B39: =IF(A39=$B$13+$D$16,($B$16*$B$9/$D$16)*(1-$B$14),IF(A39<$B$13+$D$16,$B$16*$B$9/$D$16,0)) -> 1200 | C39: =IF(A39=$B$13+$D$17,($B$17*$B$9/$D$17)*(1-$B$14),IF(A39<$B$13+$D$17,$B$17*$B$9/$D$17,0)) -> 562.5 | D39: =IF(A39=$B$13+$D$18,($B$18*$B$9/$D$18)*(1-$B$14),IF(A39<$B$13+$D$18,$B$18*$B$9/$D$18,0)) -> 900 | E39: =IF(A39=$B$13+$D$19,($B$19*$B$9/$D$19)*(1-$B$14),IF(A39<$B$13+$D$19,$B$19*$B$9/$D$19,0)) -> 1500 | F39: =IF(A39=$B$13+$D$20,($B$20/$D$20)*(1-$B$14),IF(A39<$B$13+$D$20,$B$20/$D$20,0)) -> 0 | G39: =SUM(B39:F39) -> 4162.5 | H39: =B39+C39 -> 1762.5 | I39: =$B$9*($B$16+$B$17)-V39 -> 57825 | J39: =$B$9*($B$18)-X39 -> 9900 | K39: =$B$9*($B$19)-Y39 -> 1500 | L39: =$B$20-Z39+AJ39 -> 0 | N39: =$B$9*$B$15 -> 22500 | O39: =SUM(I39:N39) -> 91725 | P39: =V38 -> 22912.5 | Q39: 0 | R39: =X38 -> 11700 | S39: =Y38 -> 19500 | T39: =Z38 -> 0 | U39: =AB38 -> 54112.5 | V39: =P39+H39 -> 24675 | W39: 0 | X39: =R39+D39 -> 12600 | Y39: =S39+E39 -> 21000 | Z39: =T39+F39 -> 0 | AB39: =SUM(V39:AA39) -> 58275
... A76: =A75+1 -> 2075 | B76: =IF(A76=$B$13+$D$16,($B$16*$B$9/$D$16)*(1-$B$14),IF(A76<$B$13+$D$16,$B$16*$B$9/$D$16,0)) -> 0 | C76: =IF(A76=$B$13+$D$17,($B$17*$B$9/$D$17)*(1-$B$14),IF(A76<$B$13+$D$17,$B$17*$B$9/$D$17,0)) -> 0 | D76: =IF(A76=$B$13+$D$18,($B$18*$B$9/$D$18)*(1-$B$14),IF(A76<$B$13+$D$18,$B$18*$B$9/$D$18,0)) -> 0 | E76: =IF(A76=$B$13+$D$19,($B$19*$B$9/$D$19)*(1-$B$14),IF(A76<$B$13+$D$19,$B$19*$B$9/$D$19,0)) -> 0 | F76: =IF(A76=$B$13+$D$20,($B$20/$D$20)*(1-$B$14),IF(A76<$B$13+$D$20,$B$20/$D$20,0)) -> 0 | G76: =SUM(B76:F76) -> 0 | H76: =B76+C76 -> 0 | I76: =$B$9*($B$16+$B$17)-V76 -> 0 | J76: =$B$9*($B$18)-X76 -> 0 | K76: =$B$9*($B$19)-Y76 -> 0 | L76: =$B$20-Z76+AJ76 -> 0 | N76: =$B$9*$B$15 -> 22500 | O76: =SUM(I76:N76) -> 22500 | P76: =V75 -> 82500 | Q76: 0 | R76: =X75 -> 22500 | S76: =Y75 -> 22500 | T76: =Z75 -> 0 | U76: =AB75 -> 127500 | V76: =P76+H76 -> 82500 | W76: 0 | X76: =R76+D76 -> 22500 | Y76: =S76+E76 -> 22500 | Z76: =T76+F76 -> 0 | AB76: =SUM(V76:AA76) -> 127500
A80: ETAPE 3 : Compte de resultat
A82: Année | B82: =F13 -> 2025 | D82: Année | E82: =F13+1 -> 2026
A83: Dotation aux ammortissements (année en cours) | B83: {=INDIRECT(ADDRESS(H13,7))} -> 4162.5 | D83: Dotation aux ammortissements (année en cours) | E83: {=INDIRECT(ADDRESS(H13+1,7))} -> 4162.5
...

Sheet LIASSES FISCALES
A1: Etape 1 prix de départ : | D1: Espace Pro : impot gouv : Déclarer : Résultat
A4: Prix d'achat | B4: 150000
A5: Frais de notaire | B5: =8000 -> 8000
A6: frais d'agence | B6: =0 -> 0
A7: Mobilier | B7: =0 -> 0
A8: Travaux à amortir | B8: =0 -> 0
A9: Base amortissable | B9: =IF(B4>0,SUM(B4:B6),IF(E4>0,E4,0)) -> 158000
A11: Etape 2 : Décomposition et amortissement
A12: Date de début d'activité | B12: 45658
A13: Année de début d'activité | B13: =YEAR(B12) -> 2025 | E13: Année d'exercice | F13: =2025 -> 2025 | H13: =F13-B13+26 -> 26
A14: Prorata | B14: =YEARFRAC(B12,DATE(YEAR(B12)+1,1,1),4) -> 1 | AD14: Travaux/Mobilier | AE14: Montant | AF14: Date debut | AG14: Nbr année amortissement | AH14: Prorata première année
A15: Terrain | B15: =15% -> 0.15 | AD15: Travaux/Mobilier 1 | AE15: 0 | AF15: 45809 | AG15: 10 | AH15: =YEARFRAC(AF15,DATE(YEAR(AF15)+1,1,1),4) -> 0.58333333
A16: Structure (Gros oeuvre) | B16: =40% -> 0.4 | C16: du total sur | D16: 50 | E16: ans | AD16: Travaux/Mobilier 2 | AE16: 0 | AF16: 46174 | AG16: 10 | AH16: =YEARFRAC(AF16,DATE(YEAR(AF16)+1,1,1),4) -> 0.58333333
A17: Façade, étanchieté | B17: =15% -> 0.15 | C17: du total sur | D17: 40 | E17: ans | AD17: Travaux/Mobilier 3 | AE17: 0 | AF17: 46539 | AG17: 10 | AH17: =YEARFRAC(AF17,DATE(YEAR(AF17)+1,1,1),4) -> 0.58333333
A18: IGT, Equipement | B18: =15% -> 0.15 | C18: du total sur | D18: 25 | E18: ans | AD18: Travaux/Mobilier 4 | AE18: 0 | AF18: 46905 | AG18: 10 | AH18: =YEARFRAC(AF18,DATE(YEAR(AF18)+1,1,1),4) -> 0.58333333
A19: Agencements (cloisons, chapes, platerie, revetement, plomberie, cablage) | B19: =15% -> 0.15 | C19: du total sur | D19: 15 | E19: ans | AD19: Travaux/Mobilier 5 | AE19: 0 | AF19: 47270 | AG19: 10 | AH19: =YEARFRAC(AF19,DATE(YEAR(AF19)+1,1,1),4) -> 0.58333333
A20: Mobilier+travaux avant 1ere location | B20: =B7+B8 -> 0 | D20: 10 | E20: ans | AD20: Travaux/Mobilier 6 | AE20: 0 | AF20: 47635 | AG20: 10 | AH20: =YEARFRAC(AF20,DATE(YEAR(AF20)+1,1,1),4) -> 0.58333333
A21: Frais de notaire | B21: =B5 -> 8000 | D21: 0 | AD21: Travaux/Mobilier 7 | AE21: 0 | AF21: 48000 | AG21: 10 | AH21: =YEARFRAC(AF21,DATE(YEAR(AF21)+1,1,1),4) -> 0.58333333
A22: Frais d'agence | B22: =B6 -> 0 | D22: 0 | AD22: Travaux/Mobilier 8 | AE22: 0 | AF22: 48000 | AG22: 10 | AH22: =YEARFRAC(AF22,DATE(YEAR(AF22)+1,1,1),4) -> 0.58333333
AD23: Travaux/Mobilier 9 | AE23: 0 | AF23: 48000 | AG23: 10 | AH23: =YEARFRAC(AF23,DATE(YEAR(AF23)+1,1,1),4) -> 0.58333333
C24: Augmentation Amortissement (dotations) | K24: Immobilisations net | Q24: Ammortissement début d'excercice | W24: Ammortissement fin exercice | AD24: Travaux/Mobilier 10 | AE24: 0 | AF24: 48000 | AG24: 10 | AH24: =YEARFRAC(AF24,DATE(YEAR(AF24)+1,1,1),4) -> 0.58333333
A25: Année | B25: Structure | C25: Façade | D25: Equipement | E25: Agencement | F25: Autres immobilisations corporelles | G25: Total Ammortissement | H25: Construction | I25: Construction | J25: Immo equipement | K25: Immo agencement | L25: Autres immobilisations corporelles | N25: Terrain | O25: Total | P25: Construction | Q25: Terrain | R25: Equipement | S25: Agencement | T25: Autres immobilisations corporelles | U25: Total | V25: Construction | W25: Terrain | X25: Equipement | Y25: Agencement | Z25: Autres immobilisations corporelles | AB25: Total
A26: 2025 | B26: =IF(A26<$B$13+$D$16,$B$16*$B$9/$D$16,0)*B14 -> 1264 | C26: =IF(A26<$B$13+$D17,$B$17*$B$9/$D$17,0)*B14 -> 592.5 | D26: =IF(A26<$B$13+$D18,$B$18*$B$9/$D$18,0)*B14 -> 948 | E26: =IF(A26<$B$13+$D$19,$B$19*$B$9/$D$19,0)*B14 -> 1580 | F26: =(IF(A26<$B$13+$D$20,$B$20/$D$20,0)*B14) -> 0 | G26: =SUM(B26:F26) -> 4384.5 | H26: =B26+C26 -> 1856.5 | I26: =$B$9*($B$16+$B$17)-V26 -> 85043.5 | J26: =$B$9*($B$18)-X26 -> 22752 | K26: =$B$9*($B$19)-Y26 -> 22120 | L26: =$B$20-Z26+AJ26 -> 0 | N26: =$B$9*$B$15 -> 23700 | O26: =SUM(I26:N26) -> 153615.5 | P26: 0 | Q26: 0 | R26: 0 | S26: 0 | T26: 0 | U26: 0 | V26: =P26+H26 -> 1856.5 | W26: 0 | X26: =R26+D26 -> 948 | Y26: =S26+E26 -> 1580 | Z26: =T26+F26 -> 0 | AB26: =SUM(V26:AA26) -> 4384.5
A27: 2026 | B27: =IF(A27=$B$13+$D$16,($B$16*$B$9/$D$16)*(1-$B$14),IF(A27<$B$13+$D$16,$B$16*$B$9/$D$16,0)) -> 1264 | C27: =IF(A27=$B$13+$D$17,($B$17*$B$9/$D$17)*(1-$B$14),IF(A27<$B$13+$D$17,$B$17*$B$9/$D$17,0)) -> 592.5 | D27: =IF(A27=$B$13+$D$18,($B$18*$B$9/$D$18)*(1-$B$14),IF(A27<$B$13+$D$18,$B$18*$B$9/$D$18,0)) -> 948 | E27: =IF(A27=$B$13+$D$19,($B$19*$B$9/$D$19)*(1-$B$14),IF(A27<$B$13+$D$19,$B$19*$B$9/$D$19,0)) -> 1580 | F27: =IF(A27=$B$13+$D$20,($B$20/$D$20)*(1-$B$14),IF(A27<$B$13+$D$20,$B$20/$D$20,0)) -> 0 | G27: =SUM(B27:F27) -> 4384.5 | H27: =B27+C27 -> 1856.5 | I27: =$B$9*($B$16+$B$17)-V27 -> 83187 | J27: =$B$9*($B$18)-X27 -> 21804 | K27: =$B$9*($B$19)-Y27 -> 20540 | L27: =$B$20-Z27+AJ27 -> 0 | N27: =$B$9*$B$15 -> 23700 | O27: =SUM(I27:N27) -> 149231 | P27: =V26 -> 1856.5 | Q27: 0 | R27: =X26 -> 948 | S27: =Y26 -> 1580 | T27: =Z26 -> 0 | U27: =AB26 -> 4384.5 | V27: =P27+H27 -> 3713 | W27: 0 | X27: =R27+D27 -> 1896 | Y27: =S27+E27 -> 3160 | Z27: =T27+F27 -> 0 | AB27: =SUM(V27:AA27) -> 8769
A28: =A27+1 -> 2027 | B28: =IF(A28=$B$13+$D$16,($B$16*$B$9/$D$16)*(1-$B$14),IF(A28<$B$13+$D$16,$B$16*$B$9/$D$16,0)) -> 1264 | C28: =IF(A28=$B$13+$D$17,($B$17*$B$9/$D$17)*(1-$B$14),IF(A28<$B$13+$D$17,$B$17*$B$9/$D$17,0)) -> 592.5 | D28: =IF(A28=$B$13+$D$18,($B$18*$B$9/$D$18)*(1-$B$14),IF(A28<$B$13+$D$18,$B$18*$B$9/$D$18,0)) -> 948 | E28: =IF(A28=$B$13+$D$19,($B$19*$B$9/$D$19)*(1-$B$14),IF(A28<$B$13+$D$19,$B$19*$B$9/$D$19,0)) -> 1580 | F28: =IF(A28=$B$13+$D$20,($B$20/$D$20)*(1-$B$14),IF(A28<$B$13+$D$20,$B$20/$D$20,0)) -> 0 | G28: =SUM(B28:F28) -> 4384.5 | H28: =B28+C28 -> 1856.5 | I28: =$B$9*($B$16+$B$17)-V28 -> 81330.5 | J28: =$B$9*($B$18)-X28 -> 20856 | K28: =$B$9*($B$19)-Y28 -> 18960 | L28: =$B$20-Z28+AJ28 -> 0 | N28: =$B$9*$B$15 -> 23700 | O28: =SUM(I28:N28) -> 144846.5 | P28: =V27 -> 3713 | Q28: 0 | R28: =X27 -> 1896 | S28: =Y27 -> 3160 | T28: =Z27 -> 0 | U28: =AB27 -> 8769 | V28: =P28+H28 -> 5569.5 | W28: 0 | X28: =R28+D28 -> 2844 | Y28: =S28+E28 -> 4740 | Z28: =T28+F28 -> 0 | AB28: =SUM(V28:AA28) -> 13153.5
A29: =A28+1 -> 2028 | B29: =IF(A29=$B$13+$D$16,($B$16*$B$9/$D$16)*(1-$B$14),IF(A29<$B$13+$D$16,$B$16*$B$9/$D$16,0)) -> 1264 | C29: =IF(A29=$B$13+$D$17,($B$17*$B$9/$D$17)*(1-$B$14),IF(A29<$B$13+$D$17,$B$17*$B$9/$D$17,0)) -> 592.5 | D29: =IF(A29=$B$13+$D$18,($B$18*$B$9/$D$18)*(1-$B$14),IF(A29<$B$13+$D$18,$B$18*$B$9/$D$18,0)) -> 948 | E29: =IF(A29=$B$13+$D$19,($B$19*$B$9/$D$19)*(1-$B$14),IF(A29<$B$13+$D$19,$B$19*$B$9/$D$19,0)) -> 1580 | F29: =IF(A29=$B$13+$D$20,($B$20/$D$20)*(1-$B$14),IF(A29<$B$13+$D$20,$B$20/$D$20,0)) -> 0 | G29: =SUM(B29:F29) -> 4384.5 | H29: =B29+C29 -> 1856.5 | I29: =$B$9*($B$16+$B$17)-V29 -> 79474 | J29: =$B$9*($B$18)-X29 -> 19908 | K29: =$B$9*($B$19)-Y29 -> 17380 | L29: =$B$20-Z29+AJ29 -> 0 | N29: =$B$9*$B$15 -> 23700 | O29: =SUM(I29:N29) -> 140462 | P29: =V28 -> 5569.5 | Q29: 0 | R29: =X28 -> 2844 | S29: =Y28 -> 4740 | T29: =Z28 -> 0 | U29: =AB28 -> 13153.5 | V29: =P29+H29 -> 7426 | W29: 0 | X29: =R29+D29 -> 3792 | Y29: =S29+E29 -> 6320 | Z29: =T29+F29 -> 0 | AB29: =SUM(V29:AA29) -> 17538
A30: =A29+1 -> 2029 | B30: =IF(A30=$B$13+$D$16,($B$16*$B$9/$D$16)*(1-$B$14),IF(A30<$B$13+$D$16,$B$16*$B$9/$D$16,0)) -> 1264 | C30: =IF(A30=$B$13+$D$17,($B$17*$B$9/$D$17)*(1-$B$14),IF(A30<$B$13+$D$17,$B$17*$B$9/$D$17,0)) -> 592.5 | D30: =IF(A30=$B$13+$D$18,($B$18*$B$9/$D$18)*(1-$B$14),IF(A30<$B$13+$D$18,$B$18*$B$9/$D$18,0)) -> 948 | E30: =IF(A30=$B$13+$D$19,($B$19*$B$9/$D$19)*(1-$B$14),IF(A30<$B$13+$D$19,$B$19*$B$9/$D$19,0)) -> 1580 | F30: =IF(A30=$B$13+$D$20,($B$20/$D$20)*(1-$B$14),IF(A30<$B$13+$D$20,$B$20/$D$20,0)) -> 0 | G30: =SUM(B30:F30) -> 4384.5 | H30: =B30+C30 -> 1856.5 | I30: =$B$9*($B$16+$B$17)-V30 -> 77617.5 | J30: =$B$9*($B$18)-X30 -> 18960 | K30: =$B$9*($B$19)-Y30 -> 15800 | L30: =$B$20-Z30+AJ30 -> 0 | N30: =$B$9*$B$15 -> 23700 | O30: =SUM(I30:N30) -> 136077.5 | P30: =V29 -> 7426 | Q30: 0 | R30: =X29 -> 3792 | S30: =Y29 -> 6320 | T30: =Z29 -> 0 | U30: =AB29 -> 17538 | V30: =P30+H30 -> 9282.5 | W30: 0 | X30: =R30+D30 -> 4740 | Y30: =S30+E30 -> 7900 | Z30: =T30+F30 -> 0 | AB30: =SUM(V30:AA30) -> 21922.5
A31: =A30+1 -> 2030 | B31: =IF(A31=$B$13+$D$16,($B$16*$B$9/$D$16)*(1-$B$14),IF(A31<$B$13+$D$16,$B$16*$B$9/$D$16,0)) -> 1264 | C31: =IF(A31=$B$13+$D$17,($B$17*$B$9/$D$17)*(1-$B$14),IF(A31<$B$13+$D$17,$B$17*$B$9/$D$17,0)) -> 592.5 | D31: =IF(A31=$B$13+$D$18,($B$18*$B$9/$D$18)*(1-$B$14),IF(A31<$B$13+$D$18,$B$18*$B$9/$D$18,0)) -> 948 | E31: =IF(A31=$B$13+$D$19,($B$19*$B$9/$D$19)*(1-$B$14),IF(A31<$B$13+$D$19,$B$19*$B$9/$D$19,0)) -> 1580 | F31: =IF(A31=$B$13+$D$20,($B$20/$D$20)*(1-$B$14),IF(A31<$B$13+$D$20,$B$20/$D$20,0)) -> 0 | G31: =SUM(B31:F31) -> 4384.5 | H31: =B31+C31 -> 1856.5 | I31: =$B$9*($B$16+$B$17)-V31 -> 75761 | J31: =$B$9*($B$18)-X31 -> 18012 | K31: =$B$9*($B$19)-Y31 -> 14220 | L31: =$B$20-Z31+AJ31 -> 0 | N31: =$B$9*$B$15 -> 23700 | O31: =SUM(I31:N31) -> 131693 | P31: =V30 -> 9282.5 | Q31: 0 | R31: =X30 -> 4740 | S31: =Y30 -> 7900 | T31: =Z30 -> 0 | U31: =AB30 -> 21922.5 | V31: =P31+H31 -> 11139 | W31: 0 | X31: =R31+D31 -> 5688 | Y31: =S31+E31 -> 9480 | Z31: =T31+F31 -> 0 | AB31: =SUM(V31:AA31) -> 26307
A32: =A31+1 -> 2031 | B32: =IF(A32=$B$13+$D$16,($B$16*$B$9/$D$16)*(1-$B$14),IF(A32<$B$13+$D$16,$B$16*$B$9/$D$16,0)) -> 1264 | C32: =IF(A32=$B$13+$D$17,($B$17*$B$9/$D$17)*(1-$B$14),IF(A32<$B$13+$D$17,$B$17*$B$9/$D$17,0)) -> 592.5 | D32: =IF(A32=$B$13+$D$18,($B$18*$B$9/$D$18)*(1-$B$14),IF(A32<$B$13+$D$18,$B$18*$B$9/$D$18,0)) -> 948 | E32: =IF(A32=$B$13+$D$19,($B$19*$B$9/$D$19)*(1-$B$14),IF(A32<$B$13+$D$19,$B$19*$B$9/$D$19,0)) -> 1580 | F32: =IF(A32=$B$13+$D$20,($B$20/$D$20)*(1-$B$14),IF(A32<$B$13+$D$20,$B$20/$D$20,0)) -> 0 | G32: =SUM(B32:F32) -> 4384.5 | H32: =B32+C32 -> 1856.5 | I32: =$B$9*($B$16+$B$17)-V32 -> 73904.5 | J32: =$B$9*($B$18)-X32 -> 17064 | K32: =$B$9*($B$19)-Y32 -> 12640 | L32: =$B$20-Z32+AJ32 -> 0 | N32: =$B$9*$B$15 -> 23700 | O32: =SUM(I32:N32) -> 127308.5 | P32: =V31 -> 11139 | Q32: 0 | R32: =X31 -> 5688 | S32: =Y31 -> 9480 | T32: =Z31 -> 0 | U32: =AB31 -> 26307 | V32: =P32+H32 -> 12995.5 | W32: 0 | X32: =R32+D32 -> 6636 | Y32: =S32+E32 -> 11060 | Z32: =T32+F32 -> 0 | AB32: =SUM(V32:AA32) -> 30691.5
A33: =A32+1 -> 2032 | B33: =IF(A33=$B$13+$D$16,($B$16*$B$9/$D$16)*(1-$B$14),IF(A33<$B$13+$D$16,$B$16*$B$9/$D$16,0)) -> 1264 | C33: =IF(A33=$B$13+$D$17,($B$17*$B$9/$D$17)*(1-$B$14),IF(A33<$B$13+$D$17,$B$17*$B$9/$D$17,0)) -> 592.5 | D33: =IF(A33=$B$13+$D$18,($B$18*$B$9/$D$18)*(1-$B$14),IF(A33<$B$13+$D$18,$B$18*$B$9/$D$18,0)) -> 948 | E33: =IF(A33=$B$13+$D$19,($B$19*$B$9/$D$19)*(1-$B$14),IF(A33<$B$13+$D$19,$B$19*$B$9/$D$19,0)) -> 1580 | F33: =IF(A33=$B$13+$D$20,($B$20/$D$20)*(1-$B$14),IF(A33<$B$13+$D$20,$B$20/$D$20,0)) -> 0 | G33: =SUM(B33:F33) -> 4384.5 | H33: =B33+C33 -> 1856.5 | I33: =$B$9*($B$16+$B$17)-V33 -> 72048 | J33: =$B$9*($B$18)-X33 -> 16116 | K33: =$B$9*($B$19)-Y33 -> 11060 | L33: =$B$20-Z33+AJ33 -> 0 | N33: =$B$9*$B$15 -> 23700 | O33: =SUM(I33:N33) -> 122924 | P33: =V32 -> 12995.5 | Q33: 0 | R33: =X32 -> 6636 | S33: =Y32 -> 11060 | T33: =Z32 -> 0 | U33: =AB32 -> 30691.5 | V33: =P33+H33 -> 14852 | W33: 0 | X33: =R33+D33 -> 7584 | Y33: =S33+E33 -> 12640 | Z33: =T33+F33 -> 0 | AB33: =SUM(V33:AA33) -> 35076
A34: =A33+1 -> 2033 | B34: =IF(A34=$B$13+$D$16,($B$16*$B$9/$D$16)*(1-$B$14),IF(A34<$B$13+$D$16,$B$16*$B$9/$D$16,0)) -> 1264 | C34: =IF(A34=$B$13+$D$17,($B$17*$B$9/$D$17)*(1-$B$14),IF(A34<$B$13+$D$17,$B$17*$B$9/$D$17,0)) -> 592.5 | D34: =IF(A34=$B$13+$D$18,($B$18*$B$9/$D$18)*(1-$B$14),IF(A34<$B$13+$D$18,$B$18*$B$9/$D$18,0)) -> 948 | E34: =IF(A34=$B$13+$D$19,($B$19*$B$9/$D$19)*(1-$B$14),IF(A34<$B$13+$D$19,$B$19*$B$9/$D$19,0)) -> 1580 | F34: =IF(A34=$B$13+$D$20,($B$20/$D$20)*(1-$B$14),IF(A34<$B$13+$D$20,$B$20/$D$20,0)) -> 0 | G34: =SUM(B34:F34) -> 4384.5 | H34: =B34+C34 -> 1856.5 | I34: =$B$9*($B$16+$B$17)-V34 -> 70191.5 | J34: =$B$9*($B$18)-X34 -> 15168 | K34: =$B$9*($B$19)-Y34 -> 9480 | L34: =$B$20-Z34+AJ34 -> 0 | N34: =$B$9*$B$15 -> 23700 | O34: =SUM(I34:N34) -> 118539.5 | P34: =V33 -> 14852 | Q34: 0 | R34: =X33 -> 7584 | S34: =Y33 -> 12640 | T34: =Z33 -> 0 | U34: =AB33 -> 35076 | V34: =P34+H34 -> 16708.5 | W34: 0 | X34: =R34+D34 -> 8532 | Y34: =S34+E34 -> 14220 | Z34: =T34+F34 -> 0 | AB34: =SUM(V34:AA34) -> 39460.5
A35: =A34+1 -> 2034 | B35: =IF(A35=$B$13+$D$16,($B$16*$B$9/$D$16)*(1-$B$14),IF(A35<$B$13+$D$16,$B$16*$B$9/$D$16,0)) -> 1264 | C35: =IF(A35=$B$13+$D$17,($B$17*$B$9/$D$17)*(1-$B$14),IF(A35<$B$13+$D$17,$B$17*$B$9/$D$17,0)) -> 592.5 | D35: =IF(A35=$B$13+$D$18,($B$18*$B$9/$D$18)*(1-$B$14),IF(A35<$B$13+$D$18,$B$18*$B$9/$D$18,0)) -> 948 | E35: =IF(A35=$B$13+$D$19,($B$19*$B$9/$D$19)*(1-$B$14),IF(A35<$B$13+$D$19,$B$19*$B$9/$D$19,0)) -> 1580 | F35: =IF(A35=$B$13+$D$20,($B$20/$D$20)*(1-$B$14),IF(A35<$B$13+$D$20,$B$20/$D$20,0)) -> 0 | G35: =SUM(B35:F35) -> 4384.5 | H35: =B35+C35 -> 1856.5 | I35: =$B$9*($B$16+$B$17)-V35 -> 68335 | J35: =$B$9*($B$18)-X35 -> 14220 | K35: =$B$9*($B$19)-Y35 -> 7900 | L35: =$B$20-Z35+AJ35 -> 0 | N35: =$B$9*$B$15 -> 23700 | O35: =SUM(I35:N35) -> 114155 | P35: =V34 -> 16708.5 | Q35: 0 | R35: =X34 -> 8532 | S35: =Y34 -> 14220 | T35: =Z34 -> 0 | U35: =AB34 -> 39460.5 | V35: =P35+H35 -> 18565 | W35: 0 | X35: =R35+D35 -> 9480 | Y35: =S35+E35 -> 15800 | Z35: =T35+F35 -> 0 | AB35: =SUM(V35:AA35) -> 43845
A36: =A35+1 -> 2035 | B36: =IF(A36=$B$13+$D$16,($B$16*$B$9/$D$16)*(1-$B$14),IF(A36<$B$13+$D$16,$B$16*$B$9/$D$16,0)) -> 1264 | C36: =IF(A36=$B$13+$D$17,($B$17*$B$9/$D$17)*(1-$B$14),IF(A36<$B$13+$D$17,$B$17*$B$9/$D$17,0)) -> 592.5 | D36: =IF(A36=$B$13+$D$18,($B$18*$B$9/$D$18)*(1-$B$14),IF(A36<$B$13+$D$18,$B$18*$B$9/$D$18,0)) -> 948 | E36: =IF(A36=$B$13+$D$19,($B$19*$B$9/$D$19)*(1-$B$14),IF(A36<$B$13+$D$19,$B$19*$B$9/$D$19,0)) -> 1580 | F36: =IF(A36=$B$13+$D$20,($B$20/$D$20)*(1-$B$14),IF(A36<$B$13+$D$20,$B$20/$D$20,0)) -> 0 | G36: =SUM(B36:F36) -> 4384.5 | H36: =B36+C36 -> 1856.5 | I36: =$B$9*($B$16+$B$17)-V36 -> 66478.5 | J36: =$B$9*($B$18)-X36 -> 13272 | K36: =$B$9*($B$19)-Y36 -> 6320 | L36: =$B$20-Z36+AJ36 -> 0 | N36: =$B$9*$B$15 -> 23700 | O36: =SUM(I36:N36) -> 109770.5 | P36: =V35 -> 18565 | Q36: 0 | R36: =X35 -> 9480 | S36: =Y35 -> 15800 | T36: =Z35 -> 0 | U36: =AB35 -> 43845 | V36: =P36+H36 -> 20421.5 | W36: 0 | X36: =R36+D36 -> 10428 | Y36: =S36+E36 -> 17380 | Z36: =T36+F36 -> 0 | AB36: =SUM(V36:AA36) -> 48229.5
A37: =A36+1 -> 2036 | B37: =IF(A37=$B$13+$D$16,($B$16*$B$9/$D$16)*(1-$B$14),IF(A37<$B$13+$D$16,$B$16*$B$9/$D$16,0)) -> 1264 | C37: =IF(A37=$B$13+$D$17,($B$17*$B$9/$D$17)*(1-$B$14),IF(A37<$B$13+$D$17,$B$17*$B$9/$D$17,0)) -> 592.5 | D37: =IF(A37=$B$13+$D$18,($B$18*$B$9/$D$18)*(1-$B$14),IF(A37<$B$13+$D$18,$B$18*$B$9/$D$18,0)) -> 948 | E37: =IF(A37=$B$13+$D$19,($B$19*$B$9/$D$19)*(1-$B$14),IF(A37<$B$13+$D$19,$B$19*$B$9/$D$19,0)) -> 1580 | F37: =IF(A37=$B$13+$D$20,($B$20/$D$20)*(1-$B$14),IF(A37<$B$13+$D$20,$B$20/$D$20,0)) -> 0 | G37: =SUM(B37:F37) -> 4384.5 | H37: =B37+C37 -> 1856.5 | I37: =$B$9*($B$16+$B$17)-V37 -> 64622 | J37: =$B$9*($B$18)-X37 -> 12324 | K37: =$B$9*($B$19)-Y37 -> 4740 | L37: =$B$20-Z37+AJ37 -> 0 | N37: =$B$9*$B$15 -> 23700 | O37: =SUM(I37:N37) -> 105386 | P37: =V36 -> 20421.5 | Q37: 0 | R37: =X36 -> 10428 | S37: =Y36 -> 17380 | T37: =Z36 -> 0 | U37: =AB36 -> 48229.5 | V37: =P37+H37 -> 22278 | W37: 0 | X37: =R37+D37 -> 11376 | Y37: =S37+E37 -> 18960 | Z37: =T37+F37 -> 0 | AB37: =SUM(V37:AA37) -> 52614
A38: =A37+1 -> 2037 | B38: =IF(A38=$B$13+$D$16,($B$16*$B$9/$D$16)*(1-$B$14),IF(A38<$B$13+$D$16,$B$16*$B$9/$D$16,0)) -> 1264 | C38: =IF(A38=$B$13+$D$17,($B$17*$B$9/$D$17)*(1-$B$14),IF(A38<$B$13+$D$17,$B$17*$B$9/$D$17,0)) -> 592.5 | D38: =IF(A38=$B$13+$D$18,($B$18*$B$9/$D$18)*(1-$B$14),IF(A38<$B$13+$D$18,$B$18*$B$9/$D$18,0)) -> 948 | E38: =IF(A38=$B$13+$D$19,($B$19*$B$9/$D$19)*(1-$B$14),IF(A38<$B$13+$D$19,$B$19*$B$9/$D$19,0)) -> 1580 | F38: =IF(A38=$B$13+$D$20,($B$20/$D$20)*(1-$B$14),IF(A38<$B$13+$D$20,$B$20/$D$20,0)) -> 0 | G38: =SUM(B38:F38) -> 4384.5 | H38: =B38+C38 -> 1856.5 | I38: =$B$9*($B$16+$B$17)-V38 -> 62765.5 | J38: =$B$9*($B$18)-X38 -> 11376 | K38: =$B$9*($B$19)-Y38 -> 3160 | L38: =$B$20-Z38+AJ38 -> 0 | N38: =$B$9*$B$15 -> 23700 | O38: =SUM(I38:N38) -> 101001.5 | P38: =V37 -> 22278 | Q38: 0 | R38: =X37 -> 11376 | S38: =Y37 -> 18960 | T38: =Z37 -> 0 | U38: =AB37 -> 52614 | V38: =P38+H38 -> 24134.5 | W38: 0 | X38: =R38+D38 -> 12324 | Y38: =S38+E38 -> 20540 | Z38: =T38+F38 -> 0 | AB38: =SUM(V38:AA38) -> 56998.5
